Workbook
Name 년: 참조!$C$3
Name 월: 참조!$C$4

Sheet 1
C1: =DATE(년,월,_xlfn.SHEET()) -> 25569.375 | P1: 금일 매출
C3: 아무것도 잡지마세요 | K3: 수당률 | M3: =SUM(K5:K12) | N3: =SUM(L5:L12)
B4: NO. | C4: 날짜/예약시간 | E4: 성함 | F4: 연락처 | G4: 주소/주요사항 | H4: 에어컨종류/개수/일반&종합 | I4: 계약금 | J4: 잔금 | K4: 합계 | L4: 수당 | P4: 순이익 | Q4: =P10-R10
B5: 1 | K5: =(I5+J5)*10000 | L5: =K5*L3
B6: 2 | K6: =(I6+J6)*10000 | L6: =K6*L3
B7: 3 | K7: =(I7+J7)*10000 | L7: =K7*L3 | P7: 수입 | R7: 지출
B8: 4 | K8: =(I8+J8)*10000 | L8: =K8*L3 | P8: 계약 | Q8: 기타 | R8: 수당비 | S8: 광고비 | T8: 기타
B9: 5 | K9: =(I9+J9)*10000 | L9: =K9*L3 | P9: =SUM(M:M) | R9: =SUM(N:N)
B10: 6 | K10: =(I10+J10)*10000 | L10: =K10*L3 | P10: =SUM(P9:Q9) | R10: =SUM(R9:T9)
B11: 7 | K11: =(I11+J11)*10000 | L11: =K11*L3
B12: 8 | K12: =(I12+J12)*10000 | L12: =K12*L3
C13: [인천시] 김의덕 기사님 [일정 여유롭게 / 벽/원/포/스탠드 사무실위주/고층사다리] | K13: 수당률 | L13: 0.5 | M13: =SUM(K15:K22) | N13: =SUM(L15:L22)
B14: NO. | C14: 날짜/예약시간 | E14: 성함 | F14: 연락처 | G14: 주소/주요사항 | H14: 에어컨종류/개수/일반&종합 | I14: 계약금 | J14: 잔금 | K14: 합계 | L14: 수당 | M14: 고층사다리
B15: 1 | C15: 4월 1일 | D15: 9시! | E15: 박상찬 | F15: 010-5582-5268 | G15: 성남시 수정구 319 산성역포레스티아 108동 2402호 1. 오전9시 시작요청 2. 방문전 사전 차량등록을 해야해서 문자로 차량번호 발송부탁드립니다. | H15: 원웨이 2대 종합 | I15: 3 | J15: 13 | K15: =(I15+J15)*10000 | L15: =K15*L13
B16: 2 | K16: =(I16+J16)*10000 | L16: =K16*L13
B17: 3 | K17: =(I17+J17)*10000 | L17: =K17*L13
B18: 4 | K18: =(I18+J18)*10000 | L18: =K18*L13
B19: 5 | K19: =(I19+J19)*10000 | L19: =K19*L13
B20: 6 | K20: =(I20+J20)*10000 | L20: =K20*L13
B21: 7 | K21: =(I21+J21)*10000 | L21: =K21*L13
B22: 8 | K22: =(I22+J22)*10000 | L22: =K22*L13
C23: [인천 서구/격주토요휴무] 신국관 기사님 [벽/원/포] | K23: 수당률 | L23: 0.5 | M23: =SUM(K25:K32) | N23: =SUM(L25:L32)
B24: NO. | C24: 날짜/예약시간 | E24: 성함 | F24: 연락처 | G24: 주소/주요사항 | H24: 에어컨종류/개수/일반&종합 | I24: 계약금 | J24: 잔금 | K24: 합계 | L24: 수당
B25: 1 | G25: 10시부터 일정 잡아주세요 | K25: =(I25+J25)*10000 | L25: =K25*L23
B26: 2 | K26: =(I26+J26)*10000 | L26: =K26*L23
B27: 3 | K27: =(I27+J27)*10000 | L27: =K27*L23
B28: 4 | K28: =(I28+J28)*10000 | L28: =K28*L23
B29: 5 | K29: =(I29+J29)*10000 | L29: =K29*L23
B30: 6 | K30: =(I30+J30)*10000 | L30: =K30*L23
B31: 7 | K31: =(I31+J31)*10000 | L31: =K31*L23
B32: 8 | K32: =(I32+J32)*10000 | L32: =K32*L23
C33: [김포시] 전상현 기사님 [일정 여유롭게 / 벽/원/스탠드 사무실위주/통] | K33: 수당률 | L33: 0.5 | M33: =SUM(K35:K42) | N33: =SUM(L35:L42)
C34: 날짜/예약시간 | E34: 성함 | F34: 연락처 | G34: 주소/주요사항 | H34: 에어컨종류/개수/일반&종합 | I34: 계약금 | J34: 잔금 | K34: 합계 | L34: 수당 | M34: 포웨이 3시간
K35: =(I35+J35)*10000 | L35: =K35*L33
K36: =(I36+J36)*10000 | L36: =K36*L33
K37: =(I37+J37)*10000 | L37: =K37*L33
K38: =(I38+J38)*10000 | L38: =K38*L33
K39: =(I39+J39)*10000 | L39: =K39*L33
K40: =(I40+J40)*10000 | L40: =K40*L33
K41: =(I41+J41)*10000 | L41: =K41*L33
...

Sheet 2
C1: =DATE(년,월,_xlfn.SHEET()) -> 25569.375 | P1: 금일 매출
C3: 아무것도 잡지마세요 | K3: 수당률 | M3: =SUM(K5:K12) | N3: =SUM(L5:L12)
B4: NO. | C4: 날짜/예약시간 | E4: 성함 | F4: 연락처 | G4: 주소/주요사항 | H4: 에어컨종류/개수/일반&종합 | I4: 계약금 | J4: 잔금 | K4: 합계 | L4: 수당 | P4: 순이익 | Q4: =P10-R10
B5: 1 | K5: =(I5+J5)*10000 | L5: =K5*L3
B6: 2 | K6: =(I6+J6)*10000 | L6: =K6*L3
B7: 3 | K7: =(I7+J7)*10000 | L7: =K7*L3 | P7: 수입 | R7: 지출
B8: 4 | K8: =(I8+J8)*10000 | L8: =K8*L3 | P8: 계약 | Q8: 기타 | R8: 수당비 | S8: 광고비 | T8: 기타
B9: 5 | K9: =(I9+J9)*10000 | L9: =K9*L3 | P9: =SUM(M:M) | R9: =SUM(N:N)
B10: 6 | K10: =(I10+J10)*10000 | L10: =K10*L3 | P10: =SUM(P9:Q9) | R10: =SUM(R9:T9)
B11: 7 | K11: =(I11+J11)*10000 | L11: =K11*L3
B12: 8 | K12: =(I12+J12)*10000 | L12: =K12*L3
C13: [인천시] 김의덕 기사님 [일정 여유롭게 / 벽/원/포/스탠드 사무실위주/고층사다리] | K13: 수당률 | L13: 0.5 | M13: =SUM(K15:K22) | N13: =SUM(L15:L22)
B14: NO. | C14: 날짜/예약시간 | E14: 성함 | F14: 연락처 | G14: 주소/주요사항 | H14: 에어컨종류/개수/일반&종합 | I14: 계약금 | J14: 잔금 | K14: 합계 | L14: 수당 | M14: 고층사다리
B15: 1 | K15: =(I15+J15)*10000 | L15: =K15*L13
B16: 2 | C16: 2 | D16: 10시~11시 | E16: 엄소영 | F16: 010-6288-3844 | G16: 금천구 금하로 23다길6 다온하우스202호 | H16: 원웨이 종합 | I16: 3 | J16: 5 | K16: =(I16+J16)*10000 | L16: =K16*L13
B17: 3 | K17: =(I17+J17)*10000 | L17: =K17*L13
B18: 4 | C18: 2 | D18: 5시~6시 | E18: 채정원 | F18: 010-4740-4659 | G18: 노원구 공릉동 218 101동 403호입니다 | H18: 원웨이 2대 종합 | I18: 3 | J18: 13 | K18: =(I18+J18)*10000 | L18: =K18*L13
B19: 5 | K19: =(I19+J19)*10000 | L19: =K19*L13
B20: 6 | K20: =(I20+J20)*10000 | L20: =K20*L13
B21: 7 | K21: =(I21+J21)*10000 | L21: =K21*L13
B22: 8 | K22: =(I22+J22)*10000 | L22: =K22*L13
C23: [인천 서구/격주토요휴무] 신국관 기사님 [벽/원/포] | K23: 수당률 | L23: 0.5 | M23: =SUM(K25:K32) | N23: =SUM(L25:L32)
B24: NO. | C24: 날짜/예약시간 | E24: 성함 | F24: 연락처 | G24: 주소/주요사항 | H24: 에어컨종류/개수/일반&종합 | I24: 계약금 | J24: 잔금 | K24: 합계 | L24: 수당
B25: 1 | G25: 10시부터 일정 잡아주세요 | K25: =(I25+J25)*10000 | L25: =K25*L23
B26: 2 | K26: =(I26+J26)*10000 | L26: =K26*L23
B27: 3 | K27: =(I27+J27)*10000 | L27: =K27*L23
B28: 4 | K28: =(I28+J28)*10000 | L28: =K28*L23
B29: 5 | C29: 2 | D29: 4시반~5시 | E29: 선서진 | F29: 010-4943-0386 | G29: 마포구 만리재로 90, 블레스하임3차오피스텔 1007호 [숨고페이] | H29: 원웨이 종합 | I29: 8 | K29: =(I29+J29)*10000 | L29: =K29*L23
B30: 6 | K30: =(I30+J30)*10000 | L30: =K30*L23
B31: 7 | K31: =(I31+J31)*10000 | L31: =K31*L23
B32: 8 | K32: =(I32+J32)*10000 | L32: =K32*L23
C33: [김포시] 전상현 기사님 [일정 여유롭게 / 벽/원/스탠드 사무실위주/통] | K33: 수당률 | L33: 0.5 | M33: =SUM(K35:K42) | N33: =SUM(L35:L42)
C34: 날짜/예약시간 | E34: 성함 | F34: 연락처 | G34: 주소/주요사항 | H34: 에어컨종류/개수/일반&종합 | I34: 계약금 | J34: 잔금 | K34: 합계 | L34: 수당 | M34: 포웨이 3시간
K35: =(I35+J35)*10000 | L35: =K35*L33
K36: =(I36+J36)*10000 | L36: =K36*L33
K37: =(I37+J37)*10000 | L37: =K37*L33
K38: =(I38+J38)*10000 | L38: =K38*L33
K39: =(I39+J39)*10000 | L39: =K39*L33
K40: =(I40+J40)*10000 | L40: =K40*L33
K41: =(I41+J41)*10000 | L41: =K41*L33
...

Sheet 3
C1: =DATE(년,월,_xlfn.SHEET()) -> 25569.375 | P1: 금일 매출
C3: 아무것도 잡지마세요 | K3: 수당률 | M3: =SUM(K5:K12) | N3: =SUM(L5:L12)
B4: NO. | C4: 날짜/예약시간 | E4: 성함 | F4: 연락처 | G4: 주소/주요사항 | H4: 에어컨종류/개수/일반&종합 | I4: 계약금 | J4: 잔금 | K4: 합계 | L4: 수당 | P4: 순이익 | Q4: =P10-R10
B5: 1 | K5: =(I5+J5)*10000 | L5: =K5*L3
B6: 2 | K6: =(I6+J6)*10000 | L6: =K6*L3
B7: 3 | K7: =(I7+J7)*10000 | L7: =K7*L3 | P7: 수입 | R7: 지출
B8: 4 | K8: =(I8+J8)*10000 | L8: =K8*L3 | P8: 계약 | Q8: 기타 | R8: 수당비 | S8: 광고비 | T8: 기타
B9: 5 | K9: =(I9+J9)*10000 | L9: =K9*L3 | P9: =SUM(M:M) | R9: =SUM(N:N)
B10: 6 | K10: =(I10+J10)*10000 | L10: =K10*L3 | P10: =SUM(P9:Q9) | R10: =SUM(R9:T9)
B11: 7 | K11: =(I11+J11)*10000 | L11: =K11*L3
B12: 8 | K12: =(I12+J12)*10000 | L12: =K12*L3
C13: [인천시] 김의덕 기사님 [일정 여유롭게 / 벽/원/포/스탠드 사무실위주/고층사다리] | K13: 수당률 | L13: 0.5 | M13: =SUM(K15:K22) | N13: =SUM(L15:L22)
B14: NO. | C14: 날짜/예약시간 | E14: 성함 | F14: 연락처 | G14: 주소/주요사항 | H14: 에어컨종류/개수/일반&종합 | I14: 계약금 | J14: 잔금 | K14: 합계 | L14: 수당 | M14: 고층사다리
B15: 1 | K15: =(I15+J15)*10000 | L15: =K15*L13
B16: 2 | K16: =(I16+J16)*10000 | L16: =K16*L13
B17: 3 | K17: =(I17+J17)*10000 | L17: =K17*L13
B18: 4 | K18: =(I18+J18)*10000 | L18: =K18*L13
B19: 5 | C19: 3 | D19: 4시반~5시 | E19: 한경석 | F19: 010-5216-6625 | G19: 안양시 동안구 비산동 1044-28 302호 | H19: 엘지 위너 스탠드 | I19: 3 | J19: 8 | K19: =(I19+J19)*10000 | L19: =K19*L13
B20: 6 | K20: =(I20+J20)*10000 | L20: =K20*L13
B21: 7 | K21: =(I21+J21)*10000 | L21: =K21*L13
B22: 8 | K22: =(I22+J22)*10000 | L22: =K22*L13
C23: [인천 서구/격주토요휴무] 신국관 기사님 [벽/원/포] | K23: 수당률 | L23: 0.5 | M23: =SUM(K25:K32) | N23: =SUM(L25:L32)
B24: NO. | C24: 날짜/예약시간 | E24: 성함 | F24: 연락처 | G24: 주소/주요사항 | H24: 에어컨종류/개수/일반&종합 | I24: 계약금 | J24: 잔금 | K24: 합계 | L24: 수당
B25: 1 | G25: 10시부터 일정 잡아주세요 | K25: =(I25+J25)*10000 | L25: =K25*L23
B26: 2 | K26: =(I26+J26)*10000 | L26: =K26*L23
B27: 3 | K27: =(I27+J27)*10000 | L27: =K27*L23
B28: 4 | K28: =(I28+J28)*10000 | L28: =K28*L23
B29: 5 | K29: =(I29+J29)*10000 | L29: =K29*L23
B30: 6 | K30: =(I30+J30)*10000 | L30: =K30*L23
B31: 7 | K31: =(I31+J31)*10000 | L31: =K31*L23
B32: 8 | K32: =(I32+J32)*10000 | L32: =K32*L23
C33: [김포시] 전상현 기사님 [일정 여유롭게 / 벽/원/스탠드 사무실위주/통] | K33: 수당률 | L33: 0.5 | M33: =SUM(K35:K42) | N33: =SUM(L35:L42)
C34: 날짜/예약시간 | E34: 성함 | F34: 연락처 | G34: 주소/주요사항 | H34: 에어컨종류/개수/일반&종합 | I34: 계약금 | J34: 잔금 | K34: 합계 | L34: 수당 | M34: 포웨이 3시간
K35: =(I35+J35)*10000 | L35: =K35*L33
K36: =(I36+J36)*10000 | L36: =K36*L33
K37: =(I37+J37)*10000 | L37: =K37*L33
K38: =(I38+J38)*10000 | L38: =K38*L33
K39: =(I39+J39)*10000 | L39: =K39*L33
K40: =(I40+J40)*10000 | L40: =K40*L33
K41: =(I41+J41)*10000 | L41: =K41*L33
...

Sheet 4
C1: =DATE(년,월,_xlfn.SHEET()) -> 25569.375 | P1: 금일 매출
C3: 아무것도 잡지마세요 | K3: 수당률 | M3: =SUM(K5:K12) | N3: =SUM(L5:L12)
B4: NO. | C4: 날짜/예약시간 | E4: 성함 | F4: 연락처 | G4: 주소/주요사항 | H4: 에어컨종류/개수/일반&종합 | I4: 계약금 | J4: 잔금 | K4: 합계 | L4: 수당 | P4: 순이익 | Q4: =P10-R10
B5: 1 | K5: =(I5+J5)*10000 | L5: =K5*L3
B6: 2 | K6: =(I6+J6)*10000 | L6: =K6*L3
B7: 3 | K7: =(I7+J7)*10000 | L7: =K7*L3 | P7: 수입 | R7: 지출
B8: 4 | K8: =(I8+J8)*10000 | L8: =K8*L3 | P8: 계약 | Q8: 기타 | R8: 수당비 | S8: 광고비 | T8: 기타
B9: 5 | K9: =(I9+J9)*10000 | L9: =K9*L3 | P9: =SUM(M:M) | R9: =SUM(N:N)
B10: 6 | K10: =(I10+J10)*10000 | L10: =K10*L3 | P10: =SUM(P9:Q9) | R10: =SUM(R9:T9)
B11: 7 | K11: =(I11+J11)*10000 | L11: =K11*L3
B12: 8 | K12: =(I12+J12)*10000 | L12: =K12*L3
C13: [인천시] 김의덕 기사님 [일정 여유롭게 / 벽/원/포/스탠드 사무실위주/고층사다리] | K13: 수당률 | L13: 0.5 | M13: =SUM(K15:K22) | N13: =SUM(L15:L22)
B14: NO. | C14: 날짜/예약시간 | E14: 성함 | F14: 연락처 | G14: 주소/주요사항 | H14: 에어컨종류/개수/일반&종합 | I14: 계약금 | J14: 잔금 | K14: 합계 | L14: 수당 | M14: 고층사다리
B15: 1 | K15: =(I15+J15)*10000 | L15: =K15*L13
B16: 2 | K16: =(I16+J16)*10000 | L16: =K16*L13
B17: 3 | K17: =(I17+J17)*10000 | L17: =K17*L13
B18: 4 | K18: =(I18+J18)*10000 | L18: =K18*L13
B19: 5 | K19: =(I19+J19)*10000 | L19: =K19*L13
B20: 6 | K20: =(I20+J20)*10000 | L20: =K20*L13
B21: 7 | K21: =(I21+J21)*10000 | L21: =K21*L13
B22: 8 | K22: =(I22+J22)*10000 | L22: =K22*L13
C23: [인천 서구/격주토요휴무] 신국관 기사님 [벽/원/포] | K23: 수당률 | L23: 0.5 | M23: =SUM(K25:K32) | N23: =SUM(L25:L32)
B24: NO. | C24: 날짜/예약시간 | E24: 성함 | F24: 연락처 | G24: 주소/주요사항 | H24: 에어컨종류/개수/일반&종합 | I24: 계약금 | J24: 잔금 | K24: 합계 | L24: 수당
B25: 1 | G25: 10시부터 일정 잡아주세요 | K25: =(I25+J25)*10000 | L25: =K25*L23
B26: 2 | K26: =(I26+J26)*10000 | L26: =K26*L23
B27: 3 | K27: =(I27+J27)*10000 | L27: =K27*L23
B28: 4 | K28: =(I28+J28)*10000 | L28: =K28*L23
B29: 5 | K29: =(I29+J29)*10000 | L29: =K29*L23
B30: 6 | K30: =(I30+J30)*10000 | L30: =K30*L23
B31: 7 | K31: =(I31+J31)*10000 | L31: =K31*L23
B32: 8 | K32: =(I32+J32)*10000 | L32: =K32*L23
C33: [김포시] 전상현 기사님 [일정 여유롭게 / 벽/원/스탠드 사무실위주/통] | K33: 수당률 | L33: 0.5 | M33: =SUM(K35:K42) | N33: =SUM(L35:L42)
C34: 날짜/예약시간 | E34: 성함 | F34: 연락처 | G34: 주소/주요사항 | H34: 에어컨종류/개수/일반&종합 | I34: 계약금 | J34: 잔금 | K34: 합계 | L34: 수당 | M34: 포웨이 3시간
K35: =(I35+J35)*10000 | L35: =K35*L33
K36: =(I36+J36)*10000 | L36: =K36*L33
K37: =(I37+J37)*10000 | L37: =K37*L33
K38: =(I38+J38)*10000 | L38: =K38*L33
K39: =(I39+J39)*10000 | L39: =K39*L33
K40: =(I40+J40)*10000 | L40: =K40*L33
K41: =(I41+J41)*10000 | L41: =K41*L33
...

Sheet 5
C1: =DATE(년,월,_xlfn.SHEET()) -> 25569.375 | P1: 금일 매출
C3: 아무것도 잡지마세요 | K3: 수당률 | M3: =SUM(K5:K12) | N3: =SUM(L5:L12)
B4: NO. | C4: 날짜/예약시간 | E4: 성함 | F4: 연락처 | G4: 주소/주요사항 | H4: 에어컨종류/개수/일반&종합 | I4: 계약금 | J4: 잔금 | K4: 합계 | L4: 수당 | P4: 순이익 | Q4: =P10-R10
B5: 1 | K5: =(I5+J5)*10000 | L5: =K5*L3
B6: 2 | K6: =(I6+J6)*10000 | L6: =K6*L3
B7: 3 | K7: =(I7+J7)*10000 | L7: =K7*L3 | P7: 수입 | R7: 지출
B8: 4 | K8: =(I8+J8)*10000 | L8: =K8*L3 | P8: 계약 | Q8: 기타 | R8: 수당비 | S8: 광고비 | T8: 기타
B9: 5 | K9: =(I9+J9)*10000 | L9: =K9*L3 | P9: =SUM(M:M) | R9: =SUM(N:N)
B10: 6 | K10: =(I10+J10)*10000 | L10: =K10*L3 | P10: =SUM(P9:Q9) | R10: =SUM(R9:T9)
B11: 7 | K11: =(I11+J11)*10000 | L11: =K11*L3
B12: 8 | K12: =(I12+J12)*10000 | L12: =K12*L3
C13: [인천시] 김의덕 기사님 [일정 여유롭게 / 벽/원/포/스탠드 사무실위주/고층사다리] | K13: 수당률 | L13: 0.5 | M13: =SUM(K15:K22) | N13: =SUM(L15:L22)
B14: NO. | C14: 날짜/예약시간 | E14: 성함 | F14: 연락처 | G14: 주소/주요사항 | H14: 에어컨종류/개수/일반&종합 | I14: 계약금 | J14: 잔금 | K14: 합계 | L14: 수당 | M14: 고층사다리
B15: 1 | K15: =(I15+J15)*10000 | L15: =K15*L13
B16: 2 | C16: 5 | D16: 11시 | E16: 김송이 | F16: 010-3942-1932 | G16: 경기도 수원시 권선구 서호서로25 303호 [세척 완료 후 전액 카드결제, 예약금 반환] | H16: 엘지 위너 투인원 종합 | I16: 3 | J16: 12 | K16: =(I16+J16)*10000 | L16: =K16*L13
B17: 3 | K17: =(I17+J17)*10000 | L17: =K17*L13
B18: 4 | K18: =(I18+J18)*10000 | L18: =K18*L13
B19: 5 | K19: =(I19+J19)*10000 | L19: =K19*L13
B20: 6 | K20: =(I20+J20)*10000 | L20: =K20*L13
B21: 7 | K21: =(I21+J21)*10000 | L21: =K21*L13
B22: 8 | K22: =(I22+J22)*10000 | L22: =K22*L13
C23: [인천 서구/격주토요휴무] 신국관 기사님 [벽/원/포] | K23: 수당률 | L23: 0.5 | M23: =SUM(K25:K32) | N23: =SUM(L25:L32)
B24: NO. | C24: 날짜/예약시간 | E24: 성함 | F24: 연락처 | G24: 주소/주요사항 | H24: 에어컨종류/개수/일반&종합 | I24: 계약금 | J24: 잔금 | K24: 합계 | L24: 수당
B25: 1 | G25: 10시부터 일정 잡아주세요 | K25: =(I25+J25)*10000 | L25: =K25*L23
B26: 2 | C26: 5 | D26: 10시! | E26: 마동차 황태림 | F26: 010-7770-9803 | G26: 서초구 서초동 1600-4 | H26: 원웨이 종합 | I26: 3 | J26: 5 | K26: =(I26+J26)*10000 | L26: =K26*L23
B27: 3 | K27: =(I27+J27)*10000 | L27: =K27*L23
B28: 4 | C28: 5 | D28: 2시~3시 | E28: 김혜영 | F28: 010-8000-2503 | G28: 파주시 송학1길 123 프리덴 302호 | H28: 원웨이 종합 2대 | I28: 3 | J28: 13 | K28: =(I28+J28)*10000 | L28: =K28*L23
B29: 5 | K29: =(I29+J29)*10000 | L29: =K29*L23
B30: 6 | K30: =(I30+J30)*10000 | L30: =K30*L23
B31: 7 | K31: =(I31+J31)*10000 | L31: =K31*L23
B32: 8 | K32: =(I32+J32)*10000 | L32: =K32*L23
C33: [김포시] 전상현 기사님 [일정 여유롭게 / 벽/원/스탠드 사무실위주/통] | K33: 수당률 | L33: 0.5 | M33: =SUM(K35:K42) | N33: =SUM(L35:L42)
C34: 날짜/예약시간 | E34: 성함 | F34: 연락처 | G34: 주소/주요사항 | H34: 에어컨종류/개수/일반&종합 | I34: 계약금 | J34: 잔금 | K34: 합계 | L34: 수당 | M34: 포웨이 3시간
K35: =(I35+J35)*10000 | L35: =K35*L33
K36: =(I36+J36)*10000 | L36: =K36*L33
C37: 5 | D37: 11시~12시 | E37: 이아름솔 | F37: 010-3020-9826 | G37: 시흥시 은계중앙로 325, 107동 1303호 | H37: 엘지 위너 투인원 종합 | I37: 3 | J37: 13 | K37: =(I37+J37)*10000 | L37: =K37*L33
K38: =(I38+J38)*10000 | L38: =K38*L33
K39: =(I39+J39)*10000 | L39: =K39*L33
K40: =(I40+J40)*10000 | L40: =K40*L33
K41: =(I41+J41)*10000 | L41: =K41*L33
...

Sheet 6
C1: =DATE(년,월,_xlfn.SHEET()) -> 25569.375 | P1: 금일 매출
C3: 아무것도 잡지마세요 | K3: 수당률 | M3: =SUM(K5:K12) | N3: =SUM(L5:L12)
B4: NO. | C4: 날짜/예약시간 | E4: 성함 | F4: 연락처 | G4: 주소/주요사항 | H4: 에어컨종류/개수/일반&종합 | I4: 계약금 | J4: 잔금 | K4: 합계 | L4: 수당 | P4: 순이익 | Q4: =P10-R10
B5: 1 | K5: =(I5+J5)*10000 | L5: =K5*L3
B6: 2 | K6: =(I6+J6)*10000 | L6: =K6*L3
B7: 3 | K7: =(I7+J7)*10000 | L7: =K7*L3 | P7: 수입 | R7: 지출
B8: 4 | K8: =(I8+J8)*10000 | L8: =K8*L3 | P8: 계약 | Q8: 기타 | R8: 수당비 | S8: 광고비 | T8: 기타
B9: 5 | K9: =(I9+J9)*10000 | L9: =K9*L3 | P9: =SUM(M:M) | R9: =SUM(N:N)
B10: 6 | K10: =(I10+J10)*10000 | L10: =K10*L3 | P10: =SUM(P9:Q9) | R10: =SUM(R9:T9)
B11: 7 | K11: =(I11+J11)*10000 | L11: =K11*L3
B12: 8 | K12: =(I12+J12)*10000 | L12: =K12*L3
C13: [인천시] 김의덕 기사님 [일정 여유롭게 / 벽/원/포/스탠드 사무실위주/고층사다리] | K13: 수당률 | L13: 0.5 | M13: =SUM(K15:K22) | N13: =SUM(L15:L22) | P13: 금주 매출
B14: NO. | C14: 날짜/예약시간 | E14: 성함 | F14: 연락처 | G14: 주소/주요사항 | H14: 에어컨종류/개수/일반&종합 | I14: 계약금 | J14: 잔금 | K14: 합계 | L14: 수당 | M14: 고층사다리
B15: 1 | K15: =(I15+J15)*10000 | L15: =K15*L13 | P15: 순이익 | Q15: =P21-R21
B16: 2 | K16: =(I16+J16)*10000 | L16: =K16*L13
B17: 3 | K17: =(I17+J17)*10000 | L17: =K17*L13
B18: 4 | K18: =(I18+J18)*10000 | L18: =K18*L13 | P18: 수입 | R18: 지출
B19: 5 | K19: =(I19+J19)*10000 | L19: =K19*L13 | P19: 계약 | Q19: 기타 | R19: 수당비 | S19: 광고비 | T19: 기타
B20: 6 | K20: =(I20+J20)*10000 | L20: =K20*L13 | P20: =SUM(P9,'8'!P9,'7'!P9,'6'!P9,'5'!P9,'4'!P9,'3'!P9) | Q20: =SUM(Q9,'8'!Q9,'7'!Q9,'6'!Q9,'5'!Q9,'4'!Q9,'3'!Q9) | R20: =SUM(R9,'8'!R9,'7'!R9,'6'!R9,'5'!R9,'4'!R9,'3'!R9) | S20: =SUM(S9,'8'!S9,'7'!S9,'6'!S9,'5'!S9,'4'!S9,'3'!S9) | T20: =SUM(T9,'8'!T9,'7'!T9,'6'!T9,'5'!T9,'4'!T9,'3'!T9)
B21: 7 | K21: =(I21+J21)*10000 | L21: =K21*L13 | P21: =SUM(P20:Q20) | R21: =SUM(R20:T20)
B22: 8 | K22: =(I22+J22)*10000 | L22: =K22*L13
C23: [인천 서구/격주토요휴무] 신국관 기사님 [벽/원/포] | K23: 수당률 | L23: 0.5 | M23: =SUM(K25:K32) | N23: =SUM(L25:L32)
B24: NO. | C24: 날짜/예약시간 | E24: 성함 | F24: 연락처 | G24: 주소/주요사항 | H24: 에어컨종류/개수/일반&종합 | I24: 계약금 | J24: 잔금 | K24: 합계 | L24: 수당
B25: 1 | G25: 10시부터 일정 잡아주세요 | K25: =(I25+J25)*10000 | L25: =K25*L23
B26: 2 | K26: =(I26+J26)*10000 | L26: =K26*L23
B27: 3 | K27: =(I27+J27)*10000 | L27: =K27*L23
B28: 4 | K28: =(I28+J28)*10000 | L28: =K28*L23
B29: 5 | K29: =(I29+J29)*10000 | L29: =K29*L23
B30: 6 | K30: =(I30+J30)*10000 | L30: =K30*L23
B31: 7 | K31: =(I31+J31)*10000 | L31: =K31*L23
B32: 8 | K32: =(I32+J32)*10000 | L32: =K32*L23
C33: [김포시] 전상현 기사님 [일정 여유롭게 / 벽/원/스탠드 사무실위주/통] | K33: 수당률 | L33: 0.5 | M33: =SUM(K35:K42) | N33: =SUM(L35:L42)
C34: 날짜/예약시간 | E34: 성함 | F34: 연락처 | G34: 주소/주요사항 | H34: 에어컨종류/개수/일반&종합 | I34: 계약금 | J34: 잔금 | K34: 합계 | L34: 수당 | M34: 포웨이 3시간
K35: =(I35+J35)*10000 | L35: =K35*L33
K36: =(I36+J36)*10000 | L36: =K36*L33
K37: =(I37+J37)*10000 | L37: =K37*L33
K38: =(I38+J38)*10000 | L38: =K38*L33
K39: =(I39+J39)*10000 | L39: =K39*L33
K40: =(I40+J40)*10000 | L40: =K40*L33
K41: =(I41+J41)*10000 | L41: =K41*L33
...

Sheet 8
C1: =DATE(년,월,_xlfn.SHEET()) -> 25569.375 | P1: 금일 매출
C3: 아무것도 잡지마세요 | K3: 수당률 | M3: =SUM(K5:K12) | N3: =SUM(L5:L12)
B4: NO. | C4: 날짜/예약시간 | E4: 성함 | F4: 연락처 | G4: 주소/주요사항 | H4: 에어컨종류/개수/일반&종합 | I4: 계약금 | J4: 잔금 | K4: 합계 | L4: 수당 | P4: 순이익 | Q4: =P10-R10
B5: 1 | K5: =(I5+J5)*10000 | L5: =K5*L3
B6: 2 | K6: =(I6+J6)*10000 | L6: =K6*L3
B7: 3 | K7: =(I7+J7)*10000 | L7: =K7*L3 | P7: 수입 | R7: 지출
B8: 4 | K8: =(I8+J8)*10000 | L8: =K8*L3 | P8: 계약 | Q8: 기타 | R8: 수당비 | S8: 광고비 | T8: 기타
B9: 5 | K9: =(I9+J9)*10000 | L9: =K9*L3 | P9: =SUM(M:M) | R9: =SUM(N:N)
B10: 6 | K10: =(I10+J10)*10000 | L10: =K10*L3 | P10: =SUM(P9:Q9) | R10: =SUM(R9:T9)
B11: 7 | K11: =(I11+J11)*10000 | L11: =K11*L3
B12: 8 | K12: =(I12+J12)*10000 | L12: =K12*L3
C13: [인천시] 김의덕 기사님 [일정 여유롭게 / 벽/원/포/스탠드 사무실위주/고층사다리] | K13: 수당률 | L13: 0.5 | M13: =SUM(K15:K22) | N13: =SUM(L15:L22)
B14: NO. | C14: 날짜/예약시간 | E14: 성함 | F14: 연락처 | G14: 주소/주요사항 | H14: 에어컨종류/개수/일반&종합 | I14: 계약금 | J14: 잔금 | K14: 합계 | L14: 수당 | M14: 고층사다리
B15: 1 | C15: 8 | D15: 9시~10시 | E15: 한숙희 | F15: 010-8976-1227 | G15: 인천 남동구 논현동 은봉로 166번길 27 논현휴먼시아 범마을 211동 103호 | H15: 삼성 무풍 2구 스탠드 | I15: 3 | J15: 8 | K15: =(I15+J15)*10000 | L15: =K15*L13
B16: 2 | K16: =(I16+J16)*10000 | L16: =K16*L13
B17: 3 | K17: =(I17+J17)*10000 | L17: =K17*L13
B18: 4 | K18: =(I18+J18)*10000 | L18: =K18*L13
B19: 5 | K19: =(I19+J19)*10000 | L19: =K19*L13
B20: 6 | K20: =(I20+J20)*10000 | L20: =K20*L13
B21: 7 | K21: =(I21+J21)*10000 | L21: =K21*L13
B22: 8 | K22: =(I22+J22)*10000 | L22: =K22*L13
C23: [인천 서구/격주토요휴무] 신국관 기사님 [벽/원/포] | K23: 수당률 | L23: 0.5 | M23: =SUM(K25:K32) | N23: =SUM(L25:L32)
B24: NO. | C24: 날짜/예약시간 | E24: 성함 | F24: 연락처 | G24: 주소/주요사항 | H24: 에어컨종류/개수/일반&종합 | I24: 계약금 | J24: 잔금 | K24: 합계 | L24: 수당
B25: 1 | G25: 10시부터 일정 잡아주세요 | K25: =(I25+J25)*10000 | L25: =K25*L23
B26: 2 | K26: =(I26+J26)*10000 | L26: =K26*L23
B27: 3 | K27: =(I27+J27)*10000 | L27: =K27*L23
B28: 4 | K28: =(I28+J28)*10000 | L28: =K28*L23
B29: 5 | K29: =(I29+J29)*10000 | L29: =K29*L23
B30: 6 | K30: =(I30+J30)*10000 | L30: =K30*L23
B31: 7 | K31: =(I31+J31)*10000 | L31: =K31*L23
B32: 8 | K32: =(I32+J32)*10000 | L32: =K32*L23
C33: [김포시] 전상현 기사님 [일정 여유롭게 / 벽/원/스탠드 사무실위주/통] | K33: 수당률 | L33: 0.5 | M33: =SUM(K35:K42) | N33: =SUM(L35:L42)
C34: 날짜/예약시간 | E34: 성함 | F34: 연락처 | G34: 주소/주요사항 | H34: 에어컨종류/개수/일반&종합 | I34: 계약금 | J34: 잔금 | K34: 합계 | L34: 수당 | M34: 포웨이 3시간
K35: =(I35+J35)*10000 | L35: =K35*L33
K36: =(I36+J36)*10000 | L36: =K36*L33
K37: =(I37+J37)*10000 | L37: =K37*L33
K38: =(I38+J38)*10000 | L38: =K38*L33
K39: =(I39+J39)*10000 | L39: =K39*L33
K40: =(I40+J40)*10000 | L40: =K40*L33
K41: =(I41+J41)*10000 | L41: =K41*L33
...

Sheet 7
C1: =DATE(년,월,_xlfn.SHEET()) -> 25569.375 | P1: 금일 매출
C3: 아무것도 잡지마세요 | K3: 수당률 | M3: =SUM(K5:K12) | N3: =SUM(L5:L12)
B4: NO. | C4: 날짜/예약시간 | E4: 성함 | F4: 연락처 | G4: 주소/주요사항 | H4: 에어컨종류/개수/일반&종합 | I4: 계약금 | J4: 잔금 | K4: 합계 | L4: 수당 | P4: 순이익 | Q4: =P10-R10
B5: 1 | K5: =(I5+J5)*10000 | L5: =K5*L3
B6: 2 | K6: =(I6+J6)*10000 | L6: =K6*L3
B7: 3 | K7: =(I7+J7)*10000 | L7: =K7*L3 | P7: 수입 | R7: 지출
B8: 4 | K8: =(I8+J8)*10000 | L8: =K8*L3 | P8: 계약 | Q8: 기타 | R8: 수당비 | S8: 광고비 | T8: 기타
B9: 5 | K9: =(I9+J9)*10000 | L9: =K9*L3 | P9: =SUM(M:M) | R9: =SUM(N:N)
B10: 6 | K10: =(I10+J10)*10000 | L10: =K10*L3 | P10: =SUM(P9:Q9) | R10: =SUM(R9:T9)
B11: 7 | K11: =(I11+J11)*10000 | L11: =K11*L3
B12: 8 | K12: =(I12+J12)*10000 | L12: =K12*L3
C13: [인천시] 김의덕 기사님 [일정 여유롭게 / 벽/원/포/스탠드 사무실위주/고층사다리] | K13: 수당률 | L13: 0.5 | M13: =SUM(K15:K22) | N13: =SUM(L15:L22)
B14: NO. | C14: 날짜/예약시간 | E14: 성함 | F14: 연락처 | G14: 주소/주요사항 | H14: 에어컨종류/개수/일반&종합 | I14: 계약금 | J14: 잔금 | K14: 합계 | L14: 수당 | M14: 고층사다리
B15: 1 | K15: =(I15+J15)*10000 | L15: =K15*L13
B16: 2 | K16: =(I16+J16)*10000 | L16: =K16*L13
B17: 3 | K17: =(I17+J17)*10000 | L17: =K17*L13
B18: 4 | K18: =(I18+J18)*10000 | L18: =K18*L13
B19: 5 | K19: =(I19+J19)*10000 | L19: =K19*L13
B20: 6 | K20: =(I20+J20)*10000 | L20: =K20*L13
B21: 7 | K21: =(I21+J21)*10000 | L21: =K21*L13
B22: 8 | K22: =(I22+J22)*10000 | L22: =K22*L13
C23: [인천 서구/격주토요휴무] 신국관 기사님 [벽/원/포] | K23: 수당률 | L23: 0.5 | M23: =SUM(K25:K32) | N23: =SUM(L25:L32)
B24: NO. | C24: 날짜/예약시간 | E24: 성함 | F24: 연락처 | G24: 주소/주요사항 | H24: 에어컨종류/개수/일반&종합 | I24: 계약금 | J24: 잔금 | K24: 합계 | L24: 수당
B25: 1 | G25: 10시부터 일정 잡아주세요 | K25: =(I25+J25)*10000 | L25: =K25*L23
B26: 2 | K26: =(I26+J26)*10000 | L26: =K26*L23
B27: 3 | K27: =(I27+J27)*10000 | L27: =K27*L23
B28: 4 | K28: =(I28+J28)*10000 | L28: =K28*L23
B29: 5 | K29: =(I29+J29)*10000 | L29: =K29*L23
B30: 6 | K30: =(I30+J30)*10000 | L30: =K30*L23
B31: 7 | K31: =(I31+J31)*10000 | L31: =K31*L23
B32: 8 | K32: =(I32+J32)*10000 | L32: =K32*L23
C33: [김포시] 전상현 기사님 [일정 여유롭게 / 벽/원/스탠드 사무실위주/통] | K33: 수당률 | L33: 0.5 | M33: =SUM(K35:K42) | N33: =SUM(L35:L42)
C34: 날짜/예약시간 | E34: 성함 | F34: 연락처 | G34: 주소/주요사항 | H34: 에어컨종류/개수/일반&종합 | I34: 계약금 | J34: 잔금 | K34: 합계 | L34: 수당 | M34: 포웨이 3시간
K35: =(I35+J35)*10000 | L35: =K35*L33
K36: =(I36+J36)*10000 | L36: =K36*L33
K37: =(I37+J37)*10000 | L37: =K37*L33
K38: =(I38+J38)*10000 | L38: =K38*L33
K39: =(I39+J39)*10000 | L39: =K39*L33
K40: =(I40+J40)*10000 | L40: =K40*L33
K41: =(I41+J41)*10000 | L41: =K41*L33
...

Sheet 9
C1: =DATE(년,월,_xlfn.SHEET()) -> 25569.375 | P1: 금일 매출
C3: 아무것도 잡지마세요 | K3: 수당률 | M3: =SUM(K5:K12) | N3: =SUM(L5:L12)
B4: NO. | C4: 날짜/예약시간 | E4: 성함 | F4: 연락처 | G4: 주소/주요사항 | H4: 에어컨종류/개수/일반&종합 | I4: 계약금 | J4: 잔금 | K4: 합계 | L4: 수당 | P4: 순이익 | Q4: =P10-R10
B5: 1 | K5: =(I5+J5)*10000 | L5: =K5*L3
B6: 2 | K6: =(I6+J6)*10000 | L6: =K6*L3
B7: 3 | K7: =(I7+J7)*10000 | L7: =K7*L3 | P7: 수입 | R7: 지출
B8: 4 | K8: =(I8+J8)*10000 | L8: =K8*L3 | P8: 계약 | Q8: 기타 | R8: 수당비 | S8: 광고비 | T8: 기타
B9: 5 | K9: =(I9+J9)*10000 | L9: =K9*L3 | P9: =SUM(M:M) | R9: =SUM(N:N)
B10: 6 | K10: =(I10+J10)*10000 | L10: =K10*L3 | P10: =SUM(P9:Q9) | R10: =SUM(R9:T9)
B11: 7 | K11: =(I11+J11)*10000 | L11: =K11*L3
B12: 8 | K12: =(I12+J12)*10000 | L12: =K12*L3
C13: [인천시] 김의덕 기사님 [일정 여유롭게 / 벽/원/포/스탠드 사무실위주/고층사다리] | K13: 수당률 | L13: 0.5 | M13: =SUM(K15:K22) | N13: =SUM(L15:L22)
B14: NO. | C14: 날짜/예약시간 | E14: 성함 | F14: 연락처 | G14: 주소/주요사항 | H14: 에어컨종류/개수/일반&종합 | I14: 계약금 | J14: 잔금 | K14: 합계 | L14: 수당 | M14: 고층사다리
B15: 1 | K15: =(I15+J15)*10000 | L15: =K15*L13
B16: 2 | C16: 9 | D16: 10시~11시 | E16: Youngrok 윤영록 | F16: 010-8966-9871 | G16: 경기 광주 머루숯길 61-12 642에비뉴 103동 503호 | H16: 원웨이 2대 종합 | I16: 3 | J16: 13 | K16: =(I16+J16)*10000 | L16: =K16*L13
B17: 3 | K17: =(I17+J17)*10000 | L17: =K17*L13
B18: 4 | K18: =(I18+J18)*10000 | L18: =K18*L13
B19: 5 | K19: =(I19+J19)*10000 | L19: =K19*L13
B20: 6 | K20: =(I20+J20)*10000 | L20: =K20*L13
B21: 7 | K21: =(I21+J21)*10000 | L21: =K21*L13
B22: 8 | K22: =(I22+J22)*10000 | L22: =K22*L13
C23: [인천 서구/격주토요휴무] 신국관 기사님 [벽/원/포] | K23: 수당률 | L23: 0.5 | M23: =SUM(K25:K32) | N23: =SUM(L25:L32)
B24: NO. | C24: 날짜/예약시간 | E24: 성함 | F24: 연락처 | G24: 주소/주요사항 | H24: 에어컨종류/개수/일반&종합 | I24: 계약금 | J24: 잔금 | K24: 합계 | L24: 수당
B25: 1 | G25: 10시부터 일정 잡아주세요 | K25: =(I25+J25)*10000 | L25: =K25*L23
B26: 2 | K26: =(I26+J26)*10000 | L26: =K26*L23
B27: 3 | K27: =(I27+J27)*10000 | L27: =K27*L23
B28: 4 | K28: =(I28+J28)*10000 | L28: =K28*L23
B29: 5 | K29: =(I29+J29)*10000 | L29: =K29*L23
B30: 6 | K30: =(I30+J30)*10000 | L30: =K30*L23
B31: 7 | K31: =(I31+J31)*10000 | L31: =K31*L23
B32: 8 | K32: =(I32+J32)*10000 | L32: =K32*L23
C33: [김포시] 전상현 기사님 [일정 여유롭게 / 벽/원/스탠드 사무실위주/통] | K33: 수당률 | L33: 0.5 | M33: =SUM(K35:K42) | N33: =SUM(L35:L42)
C34: 날짜/예약시간 | E34: 성함 | F34: 연락처 | G34: 주소/주요사항 | H34: 에어컨종류/개수/일반&종합 | I34: 계약금 | J34: 잔금 | K34: 합계 | L34: 수당 | M34: 포웨이 3시간
K35: =(I35+J35)*10000 | L35: =K35*L33
K36: =(I36+J36)*10000 | L36: =K36*L33
K37: =(I37+J37)*10000 | L37: =K37*L33
K38: =(I38+J38)*10000 | L38: =K38*L33
K39: =(I39+J39)*10000 | L39: =K39*L33
K40: =(I40+J40)*10000 | L40: =K40*L33
K41: =(I41+J41)*10000 | L41: =K41*L33
...

Sheet 10
C1: =DATE(년,월,_xlfn.SHEET()) -> 25569.375 | P1: 금일 매출
C3: 아무것도 잡지마세요 | K3: 수당률 | M3: =SUM(K5:K12) | N3: =SUM(L5:L12)
B4: NO. | C4: 날짜/예약시간 | E4: 성함 | F4: 연락처 | G4: 주소/주요사항 | H4: 에어컨종류/개수/일반&종합 | I4: 계약금 | J4: 잔금 | K4: 합계 | L4: 수당 | P4: 순이익 | Q4: =P10-R10
B5: 1 | K5: =(I5+J5)*10000 | L5: =K5*L3
B6: 2 | K6: =(I6+J6)*10000 | L6: =K6*L3
B7: 3 | K7: =(I7+J7)*10000 | L7: =K7*L3 | P7: 수입 | R7: 지출
B8: 4 | K8: =(I8+J8)*10000 | L8: =K8*L3 | P8: 계약 | Q8: 기타 | R8: 수당비 | S8: 광고비 | T8: 기타
B9: 5 | K9: =(I9+J9)*10000 | L9: =K9*L3 | P9: =SUM(M:M) | R9: =SUM(N:N)
B10: 6 | K10: =(I10+J10)*10000 | L10: =K10*L3 | P10: =SUM(P9:Q9) | R10: =SUM(R9:T9)
B11: 7 | K11: =(I11+J11)*10000 | L11: =K11*L3
B12: 8 | K12: =(I12+J12)*10000 | L12: =K12*L3
C13: [인천시] 김의덕 기사님 [일정 여유롭게 / 벽/원/포/스탠드 사무실위주/고층사다리] | K13: 수당률 | L13: 0.5 | M13: =SUM(K15:K22) | N13: =SUM(L15:L22)
B14: NO. | C14: 날짜/예약시간 | E14: 성함 | F14: 연락처 | G14: 주소/주요사항 | H14: 에어컨종류/개수/일반&종합 | I14: 계약금 | J14: 잔금 | K14: 합계 | L14: 수당 | M14: 고층사다리
B15: 1 | K15: =(I15+J15)*10000 | L15: =K15*L13
B16: 2 | K16: =(I16+J16)*10000 | L16: =K16*L13
B17: 3 | K17: =(I17+J17)*10000 | L17: =K17*L13
B18: 4 | K18: =(I18+J18)*10000 | L18: =K18*L13
B19: 5 | K19: =(I19+J19)*10000 | L19: =K19*L13
B20: 6 | K20: =(I20+J20)*10000 | L20: =K20*L13
B21: 7 | K21: =(I21+J21)*10000 | L21: =K21*L13
B22: 8 | K22: =(I22+J22)*10000 | L22: =K22*L13
C23: [인천 서구/격주토요휴무] 신국관 기사님 [벽/원/포] | K23: 수당률 | L23: 0.5 | M23: =SUM(K25:K32) | N23: =SUM(L25:L32)
B24: NO. | C24: 날짜/예약시간 | E24: 성함 | F24: 연락처 | G24: 주소/주요사항 | H24: 에어컨종류/개수/일반&종합 | I24: 계약금 | J24: 잔금 | K24: 합계 | L24: 수당
B25: 1 | G25: 10시부터 일정 잡아주세요 | K25: =(I25+J25)*10000 | L25: =K25*L23
B26: 2 | K26: =(I26+J26)*10000 | L26: =K26*L23
B27: 3 | K27: =(I27+J27)*10000 | L27: =K27*L23
B28: 4 | K28: =(I28+J28)*10000 | L28: =K28*L23
B29: 5 | K29: =(I29+J29)*10000 | L29: =K29*L23
B30: 6 | K30: =(I30+J30)*10000 | L30: =K30*L23
B31: 7 | K31: =(I31+J31)*10000 | L31: =K31*L23
B32: 8 | K32: =(I32+J32)*10000 | L32: =K32*L23
C33: [김포시] 전상현 기사님 [일정 여유롭게 / 벽/원/스탠드 사무실위주/통] | K33: 수당률 | L33: 0.5 | M33: =SUM(K35:K42) | N33: =SUM(L35:L42)
C34: 날짜/예약시간 | E34: 성함 | F34: 연락처 | G34: 주소/주요사항 | H34: 에어컨종류/개수/일반&종합 | I34: 계약금 | J34: 잔금 | K34: 합계 | L34: 수당 | M34: 포웨이 3시간
K35: =(I35+J35)*10000 | L35: =K35*L33
K36: =(I36+J36)*10000 | L36: =K36*L33
K37: =(I37+J37)*10000 | L37: =K37*L33
K38: =(I38+J38)*10000 | L38: =K38*L33
K39: =(I39+J39)*10000 | L39: =K39*L33
K40: =(I40+J40)*10000 | L40: =K40*L33
K41: =(I41+J41)*10000 | L41: =K41*L33
...

Sheet 11
C1: =DATE(년,월,_xlfn.SHEET()) -> 25569.375 | P1: 금일 매출
C3: 아무것도 잡지마세요 | K3: 수당률 | M3: =SUM(K5:K12) | N3: =SUM(L5:L12)
B4: NO. | C4: 날짜/예약시간 | E4: 성함 | F4: 연락처 | G4: 주소/주요사항 | H4: 에어컨종류/개수/일반&종합 | I4: 계약금 | J4: 잔금 | K4: 합계 | L4: 수당 | P4: 순이익 | Q4: =P10-R10
B5: 1 | K5: =(I5+J5)*10000 | L5: =K5*L3
B6: 2 | K6: =(I6+J6)*10000 | L6: =K6*L3
B7: 3 | K7: =(I7+J7)*10000 | L7: =K7*L3 | P7: 수입 | R7: 지출
B8: 4 | K8: =(I8+J8)*10000 | L8: =K8*L3 | P8: 계약 | Q8: 기타 | R8: 수당비 | S8: 광고비 | T8: 기타
B9: 5 | K9: =(I9+J9)*10000 | L9: =K9*L3 | P9: =SUM(M:M) | R9: =SUM(N:N)
B10: 6 | K10: =(I10+J10)*10000 | L10: =K10*L3 | P10: =SUM(P9:Q9) | R10: =SUM(R9:T9)
B11: 7 | K11: =(I11+J11)*10000 | L11: =K11*L3
B12: 8 | K12: =(I12+J12)*10000 | L12: =K12*L3
C13: [인천시] 김의덕 기사님 [일정 여유롭게 / 벽/원/포/스탠드 사무실위주/고층사다리] | K13: 수당률 | L13: 0.5 | M13: =SUM(K15:K22) | N13: =SUM(L15:L22)
B14: NO. | C14: 날짜/예약시간 | E14: 성함 | F14: 연락처 | G14: 주소/주요사항 | H14: 에어컨종류/개수/일반&종합 | I14: 계약금 | J14: 잔금 | K14: 합계 | L14: 수당 | M14: 고층사다리
B15: 1 | K15: =(I15+J15)*10000 | L15: =K15*L13
B16: 2 | K16: =(I16+J16)*10000 | L16: =K16*L13
B17: 3 | K17: =(I17+J17)*10000 | L17: =K17*L13
B18: 4 | K18: =(I18+J18)*10000 | L18: =K18*L13
B19: 5 | K19: =(I19+J19)*10000 | L19: =K19*L13
B20: 6 | K20: =(I20+J20)*10000 | L20: =K20*L13
B21: 7 | K21: =(I21+J21)*10000 | L21: =K21*L13
B22: 8 | K22: =(I22+J22)*10000 | L22: =K22*L13
C23: [인천 서구/격주토요휴무] 신국관 기사님 [벽/원/포] | K23: 수당률 | L23: 0.5 | M23: =SUM(K25:K32) | N23: =SUM(L25:L32)
B24: NO. | C24: 날짜/예약시간 | E24: 성함 | F24: 연락처 | G24: 주소/주요사항 | H24: 에어컨종류/개수/일반&종합 | I24: 계약금 | J24: 잔금 | K24: 합계 | L24: 수당
B25: 1 | G25: 10시부터 일정 잡아주세요 | K25: =(I25+J25)*10000 | L25: =K25*L23
B26: 2 | K26: =(I26+J26)*10000 | L26: =K26*L23
B27: 3 | K27: =(I27+J27)*10000 | L27: =K27*L23
B28: 4 | K28: =(I28+J28)*10000 | L28: =K28*L23
B29: 5 | K29: =(I29+J29)*10000 | L29: =K29*L23
B30: 6 | K30: =(I30+J30)*10000 | L30: =K30*L23
B31: 7 | K31: =(I31+J31)*10000 | L31: =K31*L23
B32: 8 | K32: =(I32+J32)*10000 | L32: =K32*L23
C33: [김포시] 전상현 기사님 [일정 여유롭게 / 벽/원/스탠드 사무실위주/통] | K33: 수당률 | L33: 0.5 | M33: =SUM(K35:K42) | N33: =SUM(L35:L42)
C34: 날짜/예약시간 | E34: 성함 | F34: 연락처 | G34: 주소/주요사항 | H34: 에어컨종류/개수/일반&종합 | I34: 계약금 | J34: 잔금 | K34: 합계 | L34: 수당 | M34: 포웨이 3시간
K35: =(I35+J35)*10000 | L35: =K35*L33
K36: =(I36+J36)*10000 | L36: =K36*L33
K37: =(I37+J37)*10000 | L37: =K37*L33
K38: =(I38+J38)*10000 | L38: =K38*L33
K39: =(I39+J39)*10000 | L39: =K39*L33
K40: =(I40+J40)*10000 | L40: =K40*L33
K41: =(I41+J41)*10000 | L41: =K41*L33
...

Sheet 12
C1: =DATE(년,월,_xlfn.SHEET()) -> 25569.375 | P1: 금일 매출
C3: 아무것도 잡지마세요 | K3: 수당률 | M3: =SUM(K5:K12) | N3: =SUM(L5:L12)
B4: NO. | C4: 날짜/예약시간 | E4: 성함 | F4: 연락처 | G4: 주소/주요사항 | H4: 에어컨종류/개수/일반&종합 | I4: 계약금 | J4: 잔금 | K4: 합계 | L4: 수당 | P4: 순이익 | Q4: =P10-R10
B5: 1 | K5: =(I5+J5)*10000 | L5: =K5*L3
B6: 2 | K6: =(I6+J6)*10000 | L6: =K6*L3
B7: 3 | K7: =(I7+J7)*10000 | L7: =K7*L3 | P7: 수입 | R7: 지출
B8: 4 | K8: =(I8+J8)*10000 | L8: =K8*L3 | P8: 계약 | Q8: 기타 | R8: 수당비 | S8: 광고비 | T8: 기타
B9: 5 | K9: =(I9+J9)*10000 | L9: =K9*L3 | P9: =SUM(M:M) | R9: =SUM(N:N)
B10: 6 | K10: =(I10+J10)*10000 | L10: =K10*L3 | P10: =SUM(P9:Q9) | R10: =SUM(R9:T9)
B11: 7 | K11: =(I11+J11)*10000 | L11: =K11*L3
B12: 8 | K12: =(I12+J12)*10000 | L12: =K12*L3
C13: [인천시] 김의덕 기사님 [일정 여유롭게 / 벽/원/포/스탠드 사무실위주/고층사다리] | K13: 수당률 | L13: 0.5 | M13: =SUM(K15:K22) | N13: =SUM(L15:L22)
B14: NO. | C14: 날짜/예약시간 | E14: 성함 | F14: 연락처 | G14: 주소/주요사항 | H14: 에어컨종류/개수/일반&종합 | I14: 계약금 | J14: 잔금 | K14: 합계 | L14: 수당 | M14: 고층사다리
B15: 1 | K15: =(I15+J15)*10000 | L15: =K15*L13
B16: 2 | K16: =(I16+J16)*10000 | L16: =K16*L13
B17: 3 | K17: =(I17+J17)*10000 | L17: =K17*L13
B18: 4 | K18: =(I18+J18)*10000 | L18: =K18*L13
B19: 5 | K19: =(I19+J19)*10000 | L19: =K19*L13
B20: 6 | K20: =(I20+J20)*10000 | L20: =K20*L13
B21: 7 | K21: =(I21+J21)*10000 | L21: =K21*L13
B22: 8 | K22: =(I22+J22)*10000 | L22: =K22*L13
C23: [인천 서구/격주토요휴무] 신국관 기사님 [벽/원/포] | K23: 수당률 | L23: 0.5 | M23: =SUM(K25:K32) | N23: =SUM(L25:L32)
B24: NO. | C24: 날짜/예약시간 | E24: 성함 | F24: 연락처 | G24: 주소/주요사항 | H24: 에어컨종류/개수/일반&종합 | I24: 계약금 | J24: 잔금 | K24: 합계 | L24: 수당
B25: 1 | G25: 10시부터 일정 잡아주세요 | K25: =(I25+J25)*10000 | L25: =K25*L23
B26: 2 | K26: =(I26+J26)*10000 | L26: =K26*L23
B27: 3 | K27: =(I27+J27)*10000 | L27: =K27*L23
B28: 4 | K28: =(I28+J28)*10000 | L28: =K28*L23
B29: 5 | K29: =(I29+J29)*10000 | L29: =K29*L23
B30: 6 | K30: =(I30+J30)*10000 | L30: =K30*L23
B31: 7 | K31: =(I31+J31)*10000 | L31: =K31*L23
B32: 8 | K32: =(I32+J32)*10000 | L32: =K32*L23
C33: [김포시] 전상현 기사님 [일정 여유롭게 / 벽/원/스탠드 사무실위주/통] | K33: 수당률 | L33: 0.5 | M33: =SUM(K35:K42) | N33: =SUM(L35:L42)
C34: 날짜/예약시간 | E34: 성함 | F34: 연락처 | G34: 주소/주요사항 | H34: 에어컨종류/개수/일반&종합 | I34: 계약금 | J34: 잔금 | K34: 합계 | L34: 수당 | M34: 포웨이 3시간
K35: =(I35+J35)*10000 | L35: =K35*L33
K36: =(I36+J36)*10000 | L36: =K36*L33
K37: =(I37+J37)*10000 | L37: =K37*L33
K38: =(I38+J38)*10000 | L38: =K38*L33
K39: =(I39+J39)*10000 | L39: =K39*L33
K40: =(I40+J40)*10000 | L40: =K40*L33
K41: =(I41+J41)*10000 | L41: =K41*L33
...

Sheet 13
C1: =DATE(년,월,_xlfn.SHEET()) -> 25569.375 | P1: 금일 매출
C3: 아무것도 잡지마세요 | K3: 수당률 | M3: =SUM(K5:K12) | N3: =SUM(L5:L12)
B4: NO. | C4: 날짜/예약시간 | E4: 성함 | F4: 연락처 | G4: 주소/주요사항 | H4: 에어컨종류/개수/일반&종합 | I4: 계약금 | J4: 잔금 | K4: 합계 | L4: 수당 | P4: 순이익 | Q4: =P10-R10
B5: 1 | K5: =(I5+J5)*10000 | L5: =K5*L3
B6: 2 | K6: =(I6+J6)*10000 | L6: =K6*L3
B7: 3 | K7: =(I7+J7)*10000 | L7: =K7*L3 | P7: 수입 | R7: 지출
B8: 4 | K8: =(I8+J8)*10000 | L8: =K8*L3 | P8: 계약 | Q8: 기타 | R8: 수당비 | S8: 광고비 | T8: 기타
B9: 5 | K9: =(I9+J9)*10000 | L9: =K9*L3 | P9: =SUM(M:M) | R9: =SUM(N:N)
B10: 6 | K10: =(I10+J10)*10000 | L10: =K10*L3 | P10: =SUM(P9:Q9) | R10: =SUM(R9:T9)
B11: 7 | K11: =(I11+J11)*10000 | L11: =K11*L3
B12: 8 | K12: =(I12+J12)*10000 | L12: =K12*L3
C13: [인천시] 김의덕 기사님 [일정 여유롭게 / 벽/원/포/스탠드 사무실위주/고층사다리] | K13: 수당률 | L13: 0.5 | M13: =SUM(K15:K22) | N13: =SUM(L15:L22) | P13: 금주 매출
B14: NO. | C14: 날짜/예약시간 | E14: 성함 | F14: 연락처 | G14: 주소/주요사항 | H14: 에어컨종류/개수/일반&종합 | I14: 계약금 | J14: 잔금 | K14: 합계 | L14: 수당 | M14: 고층사다리
B15: 1 | K15: =(I15+J15)*10000 | L15: =K15*L13 | P15: 순이익 | Q15: =P21-R21
B16: 2 | K16: =(I16+J16)*10000 | L16: =K16*L13
B17: 3 | K17: =(I17+J17)*10000 | L17: =K17*L13
B18: 4 | K18: =(I18+J18)*10000 | L18: =K18*L13 | P18: 수입 | R18: 지출
B19: 5 | K19: =(I19+J19)*10000 | L19: =K19*L13 | P19: 계약 | Q19: 기타 | R19: 수당비 | S19: 광고비 | T19: 기타
B20: 6 | K20: =(I20+J20)*10000 | L20: =K20*L13 | P20: =SUM(P9,'8'!P9,'7'!P9,'6'!P9,'5'!P9,'4'!P9,'3'!P9) | Q20: =SUM(Q9,'8'!Q9,'7'!Q9,'6'!Q9,'5'!Q9,'4'!Q9,'3'!Q9) | R20: =SUM(R9,'8'!R9,'7'!R9,'6'!R9,'5'!R9,'4'!R9,'3'!R9) | S20: =SUM(S9,'8'!S9,'7'!S9,'6'!S9,'5'!S9,'4'!S9,'3'!S9) | T20: =SUM(T9,'8'!T9,'7'!T9,'6'!T9,'5'!T9,'4'!T9,'3'!T9)
B21: 7 | K21: =(I21+J21)*10000 | L21: =K21*L13 | P21: =SUM(P20:Q20) | R21: =SUM(R20:T20)
B22: 8 | K22: =(I22+J22)*10000 | L22: =K22*L13
C23: [인천 서구/격주토요휴무] 신국관 기사님 [벽/원/포] | K23: 수당률 | L23: 0.5 | M23: =SUM(K25:K32) | N23: =SUM(L25:L32)
B24: NO. | C24: 날짜/예약시간 | E24: 성함 | F24: 연락처 | G24: 주소/주요사항 | H24: 에어컨종류/개수/일반&종합 | I24: 계약금 | J24: 잔금 | K24: 합계 | L24: 수당
B25: 1 | G25: 10시부터 일정 잡아주세요 | K25: =(I25+J25)*10000 | L25: =K25*L23
B26: 2 | K26: =(I26+J26)*10000 | L26: =K26*L23
B27: 3 | K27: =(I27+J27)*10000 | L27: =K27*L23
B28: 4 | K28: =(I28+J28)*10000 | L28: =K28*L23
B29: 5 | K29: =(I29+J29)*10000 | L29: =K29*L23
B30: 6 | K30: =(I30+J30)*10000 | L30: =K30*L23
B31: 7 | K31: =(I31+J31)*10000 | L31: =K31*L23
B32: 8 | K32: =(I32+J32)*10000 | L32: =K32*L23
C33: [김포시] 전상현 기사님 [일정 여유롭게 / 벽/원/스탠드 사무실위주/통] | K33: 수당률 | L33: 0.5 | M33: =SUM(K35:K42) | N33: =SUM(L35:L42)
C34: 날짜/예약시간 | E34: 성함 | F34: 연락처 | G34: 주소/주요사항 | H34: 에어컨종류/개수/일반&종합 | I34: 계약금 | J34: 잔금 | K34: 합계 | L34: 수당 | M34: 포웨이 3시간
K35: =(I35+J35)*10000 | L35: =K35*L33
K36: =(I36+J36)*10000 | L36: =K36*L33
K37: =(I37+J37)*10000 | L37: =K37*L33
K38: =(I38+J38)*10000 | L38: =K38*L33
K39: =(I39+J39)*10000 | L39: =K39*L33
K40: =(I40+J40)*10000 | L40: =K40*L33
K41: =(I41+J41)*10000 | L41: =K41*L33
...

Sheet 14
C1: =DATE(년,월,_xlfn.SHEET()) -> 25569.375 | P1: 금일 매출
C3: 아무것도 잡지마세요 | K3: 수당률 | M3: =SUM(K5:K12) | N3: =SUM(L5:L12)
B4: NO. | C4: 날짜/예약시간 | E4: 성함 | F4: 연락처 | G4: 주소/주요사항 | H4: 에어컨종류/개수/일반&종합 | I4: 계약금 | J4: 잔금 | K4: 합계 | L4: 수당 | P4: 순이익 | Q4: =P10-R10
B5: 1 | K5: =(I5+J5)*10000 | L5: =K5*L3
B6: 2 | K6: =(I6+J6)*10000 | L6: =K6*L3
B7: 3 | K7: =(I7+J7)*10000 | L7: =K7*L3 | P7: 수입 | R7: 지출
B8: 4 | K8: =(I8+J8)*10000 | L8: =K8*L3 | P8: 계약 | Q8: 기타 | R8: 수당비 | S8: 광고비 | T8: 기타
B9: 5 | K9: =(I9+J9)*10000 | L9: =K9*L3 | P9: =SUM(M:M) | R9: =SUM(N:N)
B10: 6 | K10: =(I10+J10)*10000 | L10: =K10*L3 | P10: =SUM(P9:Q9) | R10: =SUM(R9:T9)
B11: 7 | K11: =(I11+J11)*10000 | L11: =K11*L3
B12: 8 | K12: =(I12+J12)*10000 | L12: =K12*L3
C13: [인천시] 김의덕 기사님 [일정 여유롭게 / 벽/원/포/스탠드 사무실위주/고층사다리] | K13: 수당률 | L13: 0.5 | M13: =SUM(K15:K22) | N13: =SUM(L15:L22)
B14: NO. | C14: 날짜/예약시간 | E14: 성함 | F14: 연락처 | G14: 주소/주요사항 | H14: 에어컨종류/개수/일반&종합 | I14: 계약금 | J14: 잔금 | K14: 합계 | L14: 수당 | M14: 고층사다리
B15: 1 | K15: =(I15+J15)*10000 | L15: =K15*L13
B16: 2 | K16: =(I16+J16)*10000 | L16: =K16*L13
B17: 3 | K17: =(I17+J17)*10000 | L17: =K17*L13
B18: 4 | K18: =(I18+J18)*10000 | L18: =K18*L13
B19: 5 | K19: =(I19+J19)*10000 | L19: =K19*L13
B20: 6 | K20: =(I20+J20)*10000 | L20: =K20*L13
B21: 7 | K21: =(I21+J21)*10000 | L21: =K21*L13
B22: 8 | K22: =(I22+J22)*10000 | L22: =K22*L13
C23: [인천 서구/격주토요휴무] 신국관 기사님 [벽/원/포] | K23: 수당률 | L23: 0.5 | M23: =SUM(K25:K32) | N23: =SUM(L25:L32)
B24: NO. | C24: 날짜/예약시간 | E24: 성함 | F24: 연락처 | G24: 주소/주요사항 | H24: 에어컨종류/개수/일반&종합 | I24: 계약금 | J24: 잔금 | K24: 합계 | L24: 수당
B25: 1 | G25: 10시부터 일정 잡아주세요 | K25: =(I25+J25)*10000 | L25: =K25*L23
B26: 2 | K26: =(I26+J26)*10000 | L26: =K26*L23
B27: 3 | K27: =(I27+J27)*10000 | L27: =K27*L23
B28: 4 | C28: 14 | D28: 2시~3시 | E28: 정한검 | F28: 010-4670-8754 | G28: 성남시 수정구 수정로217번길21 A동 101호 | H28: 벽걸이 종합 | I28: 3 | J28: 5 | K28: =(I28+J28)*10000 | L28: =K28*L23
B29: 5 | K29: =(I29+J29)*10000 | L29: =K29*L23
B30: 6 | K30: =(I30+J30)*10000 | L30: =K30*L23
B31: 7 | K31: =(I31+J31)*10000 | L31: =K31*L23
B32: 8 | K32: =(I32+J32)*10000 | L32: =K32*L23
C33: [김포시] 전상현 기사님 [일정 여유롭게 / 벽/원/스탠드 사무실위주/통] | K33: 수당률 | L33: 0.5 | M33: =SUM(K35:K42) | N33: =SUM(L35:L42)
C34: 날짜/예약시간 | E34: 성함 | F34: 연락처 | G34: 주소/주요사항 | H34: 에어컨종류/개수/일반&종합 | I34: 계약금 | J34: 잔금 | K34: 합계 | L34: 수당 | M34: 포웨이 3시간
K35: =(I35+J35)*10000 | L35: =K35*L33
K36: =(I36+J36)*10000 | L36: =K36*L33
K37: =(I37+J37)*10000 | L37: =K37*L33
K38: =(I38+J38)*10000 | L38: =K38*L33
K39: =(I39+J39)*10000 | L39: =K39*L33
K40: =(I40+J40)*10000 | L40: =K40*L33
K41: =(I41+J41)*10000 | L41: =K41*L33
...

Sheet 15
C1: =DATE(년,월,_xlfn.SHEET()) -> 25569.375 | P1: 금일 매출
C3: 아무것도 잡지마세요 | K3: 수당률 | M3: =SUM(K5:K12) | N3: =SUM(L5:L12)
B4: NO. | C4: 날짜/예약시간 | E4: 성함 | F4: 연락처 | G4: 주소/주요사항 | H4: 에어컨종류/개수/일반&종합 | I4: 계약금 | J4: 잔금 | K4: 합계 | L4: 수당 | P4: 순이익 | Q4: =P10-R10
B5: 1 | K5: =(I5+J5)*10000 | L5: =K5*L3
B6: 2 | K6: =(I6+J6)*10000 | L6: =K6*L3
B7: 3 | K7: =(I7+J7)*10000 | L7: =K7*L3 | P7: 수입 | R7: 지출
B8: 4 | K8: =(I8+J8)*10000 | L8: =K8*L3 | P8: 계약 | Q8: 기타 | R8: 수당비 | S8: 광고비 | T8: 기타
B9: 5 | K9: =(I9+J9)*10000 | L9: =K9*L3 | P9: =SUM(M:M) | R9: =SUM(N:N)
B10: 6 | K10: =(I10+J10)*10000 | L10: =K10*L3 | P10: =SUM(P9:Q9) | R10: =SUM(R9:T9)
B11: 7 | K11: =(I11+J11)*10000 | L11: =K11*L3
B12: 8 | K12: =(I12+J12)*10000 | L12: =K12*L3
C13: [인천시] 김의덕 기사님 [일정 여유롭게 / 벽/원/포/스탠드 사무실위주/고층사다리] | K13: 수당률 | L13: 0.5 | M13: =SUM(K15:K22) | N13: =SUM(L15:L22)
B14: NO. | C14: 날짜/예약시간 | E14: 성함 | F14: 연락처 | G14: 주소/주요사항 | H14: 에어컨종류/개수/일반&종합 | I14: 계약금 | J14: 잔금 | K14: 합계 | L14: 수당 | M14: 고층사다리
B15: 1 | K15: =(I15+J15)*10000 | L15: =K15*L13
B16: 2 | K16: =(I16+J16)*10000 | L16: =K16*L13
B17: 3 | K17: =(I17+J17)*10000 | L17: =K17*L13
B18: 4 | K18: =(I18+J18)*10000 | L18: =K18*L13
B19: 5 | K19: =(I19+J19)*10000 | L19: =K19*L13
B20: 6 | K20: =(I20+J20)*10000 | L20: =K20*L13
B21: 7 | K21: =(I21+J21)*10000 | L21: =K21*L13
B22: 8 | K22: =(I22+J22)*10000 | L22: =K22*L13
C23: [인천 서구/격주토요휴무] 신국관 기사님 [벽/원/포] | K23: 수당률 | L23: 0.5 | M23: =SUM(K25:K32) | N23: =SUM(L25:L32)
B24: NO. | C24: 날짜/예약시간 | E24: 성함 | F24: 연락처 | G24: 주소/주요사항 | H24: 에어컨종류/개수/일반&종합 | I24: 계약금 | J24: 잔금 | K24: 합계 | L24: 수당
B25: 1 | G25: 10시부터 일정 잡아주세요 | K25: =(I25+J25)*10000 | L25: =K25*L23
B26: 2 | K26: =(I26+J26)*10000 | L26: =K26*L23
B27: 3 | K27: =(I27+J27)*10000 | L27: =K27*L23
B28: 4 | K28: =(I28+J28)*10000 | L28: =K28*L23
B29: 5 | K29: =(I29+J29)*10000 | L29: =K29*L23
B30: 6 | K30: =(I30+J30)*10000 | L30: =K30*L23
B31: 7 | K31: =(I31+J31)*10000 | L31: =K31*L23
B32: 8 | K32: =(I32+J32)*10000 | L32: =K32*L23
C33: [김포시] 전상현 기사님 [일정 여유롭게 / 벽/원/스탠드 사무실위주/통] | K33: 수당률 | L33: 0.5 | M33: =SUM(K35:K42) | N33: =SUM(L35:L42)
C34: 날짜/예약시간 | E34: 성함 | F34: 연락처 | G34: 주소/주요사항 | H34: 에어컨종류/개수/일반&종합 | I34: 계약금 | J34: 잔금 | K34: 합계 | L34: 수당 | M34: 포웨이 3시간
K35: =(I35+J35)*10000 | L35: =K35*L33
K36: =(I36+J36)*10000 | L36: =K36*L33
K37: =(I37+J37)*10000 | L37: =K37*L33
K38: =(I38+J38)*10000 | L38: =K38*L33
K39: =(I39+J39)*10000 | L39: =K39*L33
K40: =(I40+J40)*10000 | L40: =K40*L33
K41: =(I41+J41)*10000 | L41: =K41*L33
...

Sheet 16
C1: =DATE(년,월,_xlfn.SHEET()) -> 25569.375 | P1: 금일 매출
C3: 아무것도 잡지마세요 | K3: 수당률 | M3: =SUM(K5:K12) | N3: =SUM(L5:L12)
B4: NO. | C4: 날짜/예약시간 | E4: 성함 | F4: 연락처 | G4: 주소/주요사항 | H4: 에어컨종류/개수/일반&종합 | I4: 계약금 | J4: 잔금 | K4: 합계 | L4: 수당 | P4: 순이익 | Q4: =P10-R10
B5: 1 | K5: =(I5+J5)*10000 | L5: =K5*L3
B6: 2 | K6: =(I6+J6)*10000 | L6: =K6*L3
B7: 3 | K7: =(I7+J7)*10000 | L7: =K7*L3 | P7: 수입 | R7: 지출
B8: 4 | K8: =(I8+J8)*10000 | L8: =K8*L3 | P8: 계약 | Q8: 기타 | R8: 수당비 | S8: 광고비 | T8: 기타
B9: 5 | K9: =(I9+J9)*10000 | L9: =K9*L3 | P9: =SUM(M:M) | R9: =SUM(N:N)
B10: 6 | K10: =(I10+J10)*10000 | L10: =K10*L3 | P10: =SUM(P9:Q9) | R10: =SUM(R9:T9)
B11: 7 | K11: =(I11+J11)*10000 | L11: =K11*L3
B12: 8 | K12: =(I12+J12)*10000 | L12: =K12*L3
C13: [인천시] 김의덕 기사님 [일정 여유롭게 / 벽/원/포/스탠드 사무실위주/고층사다리] | K13: 수당률 | L13: 0.5 | M13: =SUM(K15:K22) | N13: =SUM(L15:L22)
B14: NO. | C14: 날짜/예약시간 | E14: 성함 | F14: 연락처 | G14: 주소/주요사항 | H14: 에어컨종류/개수/일반&종합 | I14: 계약금 | J14: 잔금 | K14: 합계 | L14: 수당 | M14: 고층사다리
B15: 1 | K15: =(I15+J15)*10000 | L15: =K15*L13
B16: 2 | K16: =(I16+J16)*10000 | L16: =K16*L13
B17: 3 | K17: =(I17+J17)*10000 | L17: =K17*L13
B18: 4 | K18: =(I18+J18)*10000 | L18: =K18*L13
B19: 5 | K19: =(I19+J19)*10000 | L19: =K19*L13
B20: 6 | K20: =(I20+J20)*10000 | L20: =K20*L13
B21: 7 | K21: =(I21+J21)*10000 | L21: =K21*L13
B22: 8 | K22: =(I22+J22)*10000 | L22: =K22*L13
C23: [인천 서구/격주토요휴무] 신국관 기사님 [벽/원/포] | K23: 수당률 | L23: 0.5 | M23: =SUM(K25:K32) | N23: =SUM(L25:L32)
B24: NO. | C24: 날짜/예약시간 | E24: 성함 | F24: 연락처 | G24: 주소/주요사항 | H24: 에어컨종류/개수/일반&종합 | I24: 계약금 | J24: 잔금 | K24: 합계 | L24: 수당
B25: 1 | G25: 10시부터 일정 잡아주세요 | K25: =(I25+J25)*10000 | L25: =K25*L23
B26: 2 | K26: =(I26+J26)*10000 | L26: =K26*L23
B27: 3 | C27: 16 | D27: 1시~2시 | E27: 윤지유 | F27: 010-7740-5863 | G27: 서초구 잠원로157 119동 313호 | H27: 벽걸이 종합 | I27: 3 | J27: 5 | K27: =(I27+J27)*10000 | L27: =K27*L23
B28: 4 | K28: =(I28+J28)*10000 | L28: =K28*L23
B29: 5 | K29: =(I29+J29)*10000 | L29: =K29*L23
B30: 6 | K30: =(I30+J30)*10000 | L30: =K30*L23
B31: 7 | K31: =(I31+J31)*10000 | L31: =K31*L23
B32: 8 | K32: =(I32+J32)*10000 | L32: =K32*L23
C33: [김포시] 전상현 기사님 [일정 여유롭게 / 벽/원/스탠드 사무실위주/통] | K33: 수당률 | L33: 0.5 | M33: =SUM(K35:K42) | N33: =SUM(L35:L42)
C34: 날짜/예약시간 | E34: 성함 | F34: 연락처 | G34: 주소/주요사항 | H34: 에어컨종류/개수/일반&종합 | I34: 계약금 | J34: 잔금 | K34: 합계 | L34: 수당 | M34: 포웨이 3시간
K35: =(I35+J35)*10000 | L35: =K35*L33
K36: =(I36+J36)*10000 | L36: =K36*L33
K37: =(I37+J37)*10000 | L37: =K37*L33
K38: =(I38+J38)*10000 | L38: =K38*L33
K39: =(I39+J39)*10000 | L39: =K39*L33
K40: =(I40+J40)*10000 | L40: =K40*L33
K41: =(I41+J41)*10000 | L41: =K41*L33
...

Sheet 17
C1: =DATE(년,월,_xlfn.SHEET()) -> 25569.375 | P1: 금일 매출
C3: 아무것도 잡지마세요 | K3: 수당률 | M3: =SUM(K5:K12) | N3: =SUM(L5:L12)
B4: NO. | C4: 날짜/예약시간 | E4: 성함 | F4: 연락처 | G4: 주소/주요사항 | H4: 에어컨종류/개수/일반&종합 | I4: 계약금 | J4: 잔금 | K4: 합계 | L4: 수당 | P4: 순이익 | Q4: =P10-R10
B5: 1 | K5: =(I5+J5)*10000 | L5: =K5*L3
B6: 2 | K6: =(I6+J6)*10000 | L6: =K6*L3
B7: 3 | K7: =(I7+J7)*10000 | L7: =K7*L3 | P7: 수입 | R7: 지출
B8: 4 | K8: =(I8+J8)*10000 | L8: =K8*L3 | P8: 계약 | Q8: 기타 | R8: 수당비 | S8: 광고비 | T8: 기타
B9: 5 | K9: =(I9+J9)*10000 | L9: =K9*L3 | P9: =SUM(M:M) | R9: =SUM(N:N)
B10: 6 | K10: =(I10+J10)*10000 | L10: =K10*L3 | P10: =SUM(P9:Q9) | R10: =SUM(R9:T9)
B11: 7 | K11: =(I11+J11)*10000 | L11: =K11*L3
B12: 8 | K12: =(I12+J12)*10000 | L12: =K12*L3
C13: [인천시] 김의덕 기사님 [일정 여유롭게 / 벽/원/포/스탠드 사무실위주/고층사다리] | K13: 수당률 | L13: 0.5 | M13: =SUM(K15:K22) | N13: =SUM(L15:L22)
B14: NO. | C14: 날짜/예약시간 | E14: 성함 | F14: 연락처 | G14: 주소/주요사항 | H14: 에어컨종류/개수/일반&종합 | I14: 계약금 | J14: 잔금 | K14: 합계 | L14: 수당 | M14: 고층사다리
B15: 1 | K15: =(I15+J15)*10000 | L15: =K15*L13
B16: 2 | K16: =(I16+J16)*10000 | L16: =K16*L13
B17: 3 | K17: =(I17+J17)*10000 | L17: =K17*L13
B18: 4 | K18: =(I18+J18)*10000 | L18: =K18*L13
B19: 5 | K19: =(I19+J19)*10000 | L19: =K19*L13
B20: 6 | K20: =(I20+J20)*10000 | L20: =K20*L13
B21: 7 | K21: =(I21+J21)*10000 | L21: =K21*L13
B22: 8 | K22: =(I22+J22)*10000 | L22: =K22*L13
C23: [인천 서구/격주토요휴무] 신국관 기사님 [벽/원/포] | K23: 수당률 | L23: 0.5 | M23: =SUM(K25:K32) | N23: =SUM(L25:L32)
B24: NO. | C24: 날짜/예약시간 | E24: 성함 | F24: 연락처 | G24: 주소/주요사항 | H24: 에어컨종류/개수/일반&종합 | I24: 계약금 | J24: 잔금 | K24: 합계 | L24: 수당
B25: 1 | G25: 10시부터 일정 잡아주세요 | K25: =(I25+J25)*10000 | L25: =K25*L23
B26: 2 | K26: =(I26+J26)*10000 | L26: =K26*L23
B27: 3 | K27: =(I27+J27)*10000 | L27: =K27*L23
B28: 4 | K28: =(I28+J28)*10000 | L28: =K28*L23
B29: 5 | K29: =(I29+J29)*10000 | L29: =K29*L23
B30: 6 | K30: =(I30+J30)*10000 | L30: =K30*L23
B31: 7 | K31: =(I31+J31)*10000 | L31: =K31*L23
B32: 8 | K32: =(I32+J32)*10000 | L32: =K32*L23
C33: [김포시] 전상현 기사님 [일정 여유롭게 / 벽/원/스탠드 사무실위주/통] | K33: 수당률 | L33: 0.5 | M33: =SUM(K35:K42) | N33: =SUM(L35:L42)
C34: 날짜/예약시간 | E34: 성함 | F34: 연락처 | G34: 주소/주요사항 | H34: 에어컨종류/개수/일반&종합 | I34: 계약금 | J34: 잔금 | K34: 합계 | L34: 수당 | M34: 포웨이 3시간
K35: =(I35+J35)*10000 | L35: =K35*L33
K36: =(I36+J36)*10000 | L36: =K36*L33
K37: =(I37+J37)*10000 | L37: =K37*L33
K38: =(I38+J38)*10000 | L38: =K38*L33
K39: =(I39+J39)*10000 | L39: =K39*L33
K40: =(I40+J40)*10000 | L40: =K40*L33
K41: =(I41+J41)*10000 | L41: =K41*L33
...

Sheet 19
C1: =DATE(년,월,_xlfn.SHEET()) -> 25569.375 | P1: 금일 매출
C3: 아무것도 잡지마세요 | K3: 수당률 | M3: =SUM(K5:K12) | N3: =SUM(L5:L12)
B4: NO. | C4: 날짜/예약시간 | E4: 성함 | F4: 연락처 | G4: 주소/주요사항 | H4: 에어컨종류/개수/일반&종합 | I4: 계약금 | J4: 잔금 | K4: 합계 | L4: 수당 | P4: 순이익 | Q4: =P10-R10
B5: 1 | K5: =(I5+J5)*10000 | L5: =K5*L3
B6: 2 | K6: =(I6+J6)*10000 | L6: =K6*L3
B7: 3 | K7: =(I7+J7)*10000 | L7: =K7*L3 | P7: 수입 | R7: 지출
B8: 4 | K8: =(I8+J8)*10000 | L8: =K8*L3 | P8: 계약 | Q8: 기타 | R8: 수당비 | S8: 광고비 | T8: 기타
B9: 5 | K9: =(I9+J9)*10000 | L9: =K9*L3 | P9: =SUM(M:M) | R9: =SUM(N:N)
B10: 6 | K10: =(I10+J10)*10000 | L10: =K10*L3 | P10: =SUM(P9:Q9) | R10: =SUM(R9:T9)
B11: 7 | K11: =(I11+J11)*10000 | L11: =K11*L3
B12: 8 | K12: =(I12+J12)*10000 | L12: =K12*L3
C13: [인천시] 김의덕 기사님 [일정 여유롭게 / 벽/원/포/스탠드 사무실위주/고층사다리] | K13: 수당률 | L13: 0.5 | M13: =SUM(K15:K22) | N13: =SUM(L15:L22)
B14: NO. | C14: 날짜/예약시간 | E14: 성함 | F14: 연락처 | G14: 주소/주요사항 | H14: 에어컨종류/개수/일반&종합 | I14: 계약금 | J14: 잔금 | K14: 합계 | L14: 수당 | M14: 고층사다리
B15: 1 | K15: =(I15+J15)*10000 | L15: =K15*L13
B16: 2 | K16: =(I16+J16)*10000 | L16: =K16*L13
B17: 3 | K17: =(I17+J17)*10000 | L17: =K17*L13
B18: 4 | K18: =(I18+J18)*10000 | L18: =K18*L13
B19: 5 | K19: =(I19+J19)*10000 | L19: =K19*L13
B20: 6 | K20: =(I20+J20)*10000 | L20: =K20*L13
B21: 7 | K21: =(I21+J21)*10000 | L21: =K21*L13
B22: 8 | K22: =(I22+J22)*10000 | L22: =K22*L13
C23: [인천 서구/격주토요휴무] 신국관 기사님 [벽/원/포] | K23: 수당률 | L23: 0.5 | M23: =SUM(K25:K32) | N23: =SUM(L25:L32)
B24: NO. | C24: 날짜/예약시간 | E24: 성함 | F24: 연락처 | G24: 주소/주요사항 | H24: 에어컨종류/개수/일반&종합 | I24: 계약금 | J24: 잔금 | K24: 합계 | L24: 수당
B25: 1 | G25: 10시부터 일정 잡아주세요 | K25: =(I25+J25)*10000 | L25: =K25*L23
B26: 2 | K26: =(I26+J26)*10000 | L26: =K26*L23
B27: 3 | K27: =(I27+J27)*10000 | L27: =K27*L23
B28: 4 | K28: =(I28+J28)*10000 | L28: =K28*L23
B29: 5 | K29: =(I29+J29)*10000 | L29: =K29*L23
B30: 6 | K30: =(I30+J30)*10000 | L30: =K30*L23
B31: 7 | K31: =(I31+J31)*10000 | L31: =K31*L23
B32: 8 | K32: =(I32+J32)*10000 | L32: =K32*L23
C33: [김포시] 전상현 기사님 [일정 여유롭게 / 벽/원/스탠드 사무실위주/통] | K33: 수당률 | L33: 0.5 | M33: =SUM(K35:K42) | N33: =SUM(L35:L42)
C34: 날짜/예약시간 | E34: 성함 | F34: 연락처 | G34: 주소/주요사항 | H34: 에어컨종류/개수/일반&종합 | I34: 계약금 | J34: 잔금 | K34: 합계 | L34: 수당 | M34: 포웨이 3시간
K35: =(I35+J35)*10000 | L35: =K35*L33
K36: =(I36+J36)*10000 | L36: =K36*L33
K37: =(I37+J37)*10000 | L37: =K37*L33
K38: =(I38+J38)*10000 | L38: =K38*L33
K39: =(I39+J39)*10000 | L39: =K39*L33
K40: =(I40+J40)*10000 | L40: =K40*L33
K41: =(I41+J41)*10000 | L41: =K41*L33
...

Sheet 18
C1: =DATE(년,월,_xlfn.SHEET()) -> 25569.375 | P1: 금일 매출
C3: 아무것도 잡지마세요 | K3: 수당률 | M3: =SUM(K5:K12) | N3: =SUM(L5:L12)
B4: NO. | C4: 날짜/예약시간 | E4: 성함 | F4: 연락처 | G4: 주소/주요사항 | H4: 에어컨종류/개수/일반&종합 | I4: 계약금 | J4: 잔금 | K4: 합계 | L4: 수당 | P4: 순이익 | Q4: =P10-R10
B5: 1 | K5: =(I5+J5)*10000 | L5: =K5*L3
B6: 2 | K6: =(I6+J6)*10000 | L6: =K6*L3
B7: 3 | K7: =(I7+J7)*10000 | L7: =K7*L3 | P7: 수입 | R7: 지출
B8: 4 | K8: =(I8+J8)*10000 | L8: =K8*L3 | P8: 계약 | Q8: 기타 | R8: 수당비 | S8: 광고비 | T8: 기타
B9: 5 | K9: =(I9+J9)*10000 | L9: =K9*L3 | P9: =SUM(M:M) | R9: =SUM(N:N)
B10: 6 | K10: =(I10+J10)*10000 | L10: =K10*L3 | P10: =SUM(P9:Q9) | R10: =SUM(R9:T9)
B11: 7 | K11: =(I11+J11)*10000 | L11: =K11*L3
B12: 8 | K12: =(I12+J12)*10000 | L12: =K12*L3
C13: [인천시] 김의덕 기사님 [일정 여유롭게 / 벽/원/포/스탠드 사무실위주/고층사다리] | K13: 수당률 | L13: 0.5 | M13: =SUM(K15:K22) | N13: =SUM(L15:L22)
B14: NO. | C14: 날짜/예약시간 | E14: 성함 | F14: 연락처 | G14: 주소/주요사항 | H14: 에어컨종류/개수/일반&종합 | I14: 계약금 | J14: 잔금 | K14: 합계 | L14: 수당 | M14: 고층사다리
B15: 1 | K15: =(I15+J15)*10000 | L15: =K15*L13
B16: 2 | K16: =(I16+J16)*10000 | L16: =K16*L13
B17: 3 | K17: =(I17+J17)*10000 | L17: =K17*L13
B18: 4 | K18: =(I18+J18)*10000 | L18: =K18*L13
B19: 5 | K19: =(I19+J19)*10000 | L19: =K19*L13
B20: 6 | K20: =(I20+J20)*10000 | L20: =K20*L13
B21: 7 | K21: =(I21+J21)*10000 | L21: =K21*L13
B22: 8 | K22: =(I22+J22)*10000 | L22: =K22*L13
C23: [인천 서구/격주토요휴무] 신국관 기사님 [벽/원/포] | K23: 수당률 | L23: 0.5 | M23: =SUM(K25:K32) | N23: =SUM(L25:L32)
B24: NO. | C24: 날짜/예약시간 | E24: 성함 | F24: 연락처 | G24: 주소/주요사항 | H24: 에어컨종류/개수/일반&종합 | I24: 계약금 | J24: 잔금 | K24: 합계 | L24: 수당
B25: 1 | G25: 10시부터 일정 잡아주세요 | K25: =(I25+J25)*10000 | L25: =K25*L23
B26: 2 | K26: =(I26+J26)*10000 | L26: =K26*L23
B27: 3 | K27: =(I27+J27)*10000 | L27: =K27*L23
B28: 4 | K28: =(I28+J28)*10000 | L28: =K28*L23
B29: 5 | K29: =(I29+J29)*10000 | L29: =K29*L23
B30: 6 | K30: =(I30+J30)*10000 | L30: =K30*L23
B31: 7 | K31: =(I31+J31)*10000 | L31: =K31*L23
B32: 8 | K32: =(I32+J32)*10000 | L32: =K32*L23
C33: [김포시] 전상현 기사님 [일정 여유롭게 / 벽/원/스탠드 사무실위주/통] | K33: 수당률 | L33: 0.5 | M33: =SUM(K35:K42) | N33: =SUM(L35:L42)
C34: 날짜/예약시간 | E34: 성함 | F34: 연락처 | G34: 주소/주요사항 | H34: 에어컨종류/개수/일반&종합 | I34: 계약금 | J34: 잔금 | K34: 합계 | L34: 수당 | M34: 포웨이 3시간
K35: =(I35+J35)*10000 | L35: =K35*L33
K36: =(I36+J36)*10000 | L36: =K36*L33
K37: =(I37+J37)*10000 | L37: =K37*L33
K38: =(I38+J38)*10000 | L38: =K38*L33
K39: =(I39+J39)*10000 | L39: =K39*L33
K40: =(I40+J40)*10000 | L40: =K40*L33
K41: =(I41+J41)*10000 | L41: =K41*L33
...

Sheet 20
C1: =DATE(년,월,_xlfn.SHEET()) -> 25569.375 | P1: 금일 매출
C3: 아무것도 잡지마세요 | K3: 수당률 | M3: =SUM(K5:K12) | N3: =SUM(L5:L12)
B4: NO. | C4: 날짜/예약시간 | E4: 성함 | F4: 연락처 | G4: 주소/주요사항 | H4: 에어컨종류/개수/일반&종합 | I4: 계약금 | J4: 잔금 | K4: 합계 | L4: 수당 | P4: 순이익 | Q4: =P10-R10
B5: 1 | K5: =(I5+J5)*10000 | L5: =K5*L3
B6: 2 | K6: =(I6+J6)*10000 | L6: =K6*L3
B7: 3 | K7: =(I7+J7)*10000 | L7: =K7*L3 | P7: 수입 | R7: 지출
B8: 4 | K8: =(I8+J8)*10000 | L8: =K8*L3 | P8: 계약 | Q8: 기타 | R8: 수당비 | S8: 광고비 | T8: 기타
B9: 5 | K9: =(I9+J9)*10000 | L9: =K9*L3 | P9: =SUM(M:M) | R9: =SUM(N:N)
B10: 6 | K10: =(I10+J10)*10000 | L10: =K10*L3 | P10: =SUM(P9:Q9) | R10: =SUM(R9:T9)
B11: 7 | K11: =(I11+J11)*10000 | L11: =K11*L3
B12: 8 | K12: =(I12+J12)*10000 | L12: =K12*L3
C13: [인천시] 김의덕 기사님 [일정 여유롭게 / 벽/원/포/스탠드 사무실위주/고층사다리] | K13: 수당률 | L13: 0.5 | M13: =SUM(K15:K22) | N13: =SUM(L15:L22) | P13: 금주 매출
B14: NO. | C14: 날짜/예약시간 | E14: 성함 | F14: 연락처 | G14: 주소/주요사항 | H14: 에어컨종류/개수/일반&종합 | I14: 계약금 | J14: 잔금 | K14: 합계 | L14: 수당 | M14: 고층사다리
B15: 1 | K15: =(I15+J15)*10000 | L15: =K15*L13 | P15: 순이익 | Q15: =P21-R21
B16: 2 | K16: =(I16+J16)*10000 | L16: =K16*L13
B17: 3 | K17: =(I17+J17)*10000 | L17: =K17*L13
B18: 4 | K18: =(I18+J18)*10000 | L18: =K18*L13 | P18: 수입 | R18: 지출
B19: 5 | K19: =(I19+J19)*10000 | L19: =K19*L13 | P19: 계약 | Q19: 기타 | R19: 수당비 | S19: 광고비 | T19: 기타
B20: 6 | K20: =(I20+J20)*10000 | L20: =K20*L13 | P20: =SUM(P9,'8'!P9,'7'!P9,'6'!P9,'5'!P9,'4'!P9,'3'!P9) | Q20: =SUM(Q9,'8'!Q9,'7'!Q9,'6'!Q9,'5'!Q9,'4'!Q9,'3'!Q9) | R20: =SUM(R9,'8'!R9,'7'!R9,'6'!R9,'5'!R9,'4'!R9,'3'!R9) | S20: =SUM(S9,'8'!S9,'7'!S9,'6'!S9,'5'!S9,'4'!S9,'3'!S9) | T20: =SUM(T9,'8'!T9,'7'!T9,'6'!T9,'5'!T9,'4'!T9,'3'!T9)
B21: 7 | K21: =(I21+J21)*10000 | L21: =K21*L13 | P21: =SUM(P20:Q20) | R21: =SUM(R20:T20)
B22: 8 | K22: =(I22+J22)*10000 | L22: =K22*L13
C23: [인천 서구/격주토요휴무] 신국관 기사님 [벽/원/포] | K23: 수당률 | L23: 0.5 | M23: =SUM(K25:K32) | N23: =SUM(L25:L32)
B24: NO. | C24: 날짜/예약시간 | E24: 성함 | F24: 연락처 | G24: 주소/주요사항 | H24: 에어컨종류/개수/일반&종합 | I24: 계약금 | J24: 잔금 | K24: 합계 | L24: 수당
B25: 1 | G25: 10시부터 일정 잡아주세요 | K25: =(I25+J25)*10000 | L25: =K25*L23
B26: 2 | K26: =(I26+J26)*10000 | L26: =K26*L23
B27: 3 | K27: =(I27+J27)*10000 | L27: =K27*L23
B28: 4 | K28: =(I28+J28)*10000 | L28: =K28*L23
B29: 5 | K29: =(I29+J29)*10000 | L29: =K29*L23
B30: 6 | K30: =(I30+J30)*10000 | L30: =K30*L23
B31: 7 | K31: =(I31+J31)*10000 | L31: =K31*L23
B32: 8 | K32: =(I32+J32)*10000 | L32: =K32*L23
C33: [김포시] 전상현 기사님 [일정 여유롭게 / 벽/원/스탠드 사무실위주/통] | K33: 수당률 | L33: 0.5 | M33: =SUM(K35:K42) | N33: =SUM(L35:L42)
C34: 날짜/예약시간 | E34: 성함 | F34: 연락처 | G34: 주소/주요사항 | H34: 에어컨종류/개수/일반&종합 | I34: 계약금 | J34: 잔금 | K34: 합계 | L34: 수당 | M34: 포웨이 3시간
K35: =(I35+J35)*10000 | L35: =K35*L33
K36: =(I36+J36)*10000 | L36: =K36*L33
K37: =(I37+J37)*10000 | L37: =K37*L33
K38: =(I38+J38)*10000 | L38: =K38*L33
K39: =(I39+J39)*10000 | L39: =K39*L33
K40: =(I40+J40)*10000 | L40: =K40*L33
K41: =(I41+J41)*10000 | L41: =K41*L33
...

Sheet 21
C1: =DATE(년,월,_xlfn.SHEET()) -> 25569.375 | P1: 금일 매출
C3: 아무것도 잡지마세요 | K3: 수당률 | M3: =SUM(K5:K12) | N3: =SUM(L5:L12)
B4: NO. | C4: 날짜/예약시간 | E4: 성함 | F4: 연락처 | G4: 주소/주요사항 | H4: 에어컨종류/개수/일반&종합 | I4: 계약금 | J4: 잔금 | K4: 합계 | L4: 수당 | P4: 순이익 | Q4: =P10-R10
B5: 1 | K5: =(I5+J5)*10000 | L5: =K5*L3
B6: 2 | K6: =(I6+J6)*10000 | L6: =K6*L3
B7: 3 | K7: =(I7+J7)*10000 | L7: =K7*L3 | P7: 수입 | R7: 지출
B8: 4 | K8: =(I8+J8)*10000 | L8: =K8*L3 | P8: 계약 | Q8: 기타 | R8: 수당비 | S8: 광고비 | T8: 기타
B9: 5 | K9: =(I9+J9)*10000 | L9: =K9*L3 | P9: =SUM(M:M) | R9: =SUM(N:N)
B10: 6 | K10: =(I10+J10)*10000 | L10: =K10*L3 | P10: =SUM(P9:Q9) | R10: =SUM(R9:T9)
B11: 7 | K11: =(I11+J11)*10000 | L11: =K11*L3
B12: 8 | K12: =(I12+J12)*10000 | L12: =K12*L3
C13: [인천시] 김의덕 기사님 [일정 여유롭게 / 벽/원/포/스탠드 사무실위주/고층사다리] | K13: 수당률 | L13: 0.5 | M13: =SUM(K15:K22) | N13: =SUM(L15:L22)
B14: NO. | C14: 날짜/예약시간 | E14: 성함 | F14: 연락처 | G14: 주소/주요사항 | H14: 에어컨종류/개수/일반&종합 | I14: 계약금 | J14: 잔금 | K14: 합계 | L14: 수당 | M14: 고층사다리
B15: 1 | K15: =(I15+J15)*10000 | L15: =K15*L13
B16: 2 | K16: =(I16+J16)*10000 | L16: =K16*L13
B17: 3 | K17: =(I17+J17)*10000 | L17: =K17*L13
B18: 4 | K18: =(I18+J18)*10000 | L18: =K18*L13
B19: 5 | K19: =(I19+J19)*10000 | L19: =K19*L13
B20: 6 | K20: =(I20+J20)*10000 | L20: =K20*L13
B21: 7 | K21: =(I21+J21)*10000 | L21: =K21*L13
B22: 8 | K22: =(I22+J22)*10000 | L22: =K22*L13
C23: [인천 서구/격주토요휴무] 신국관 기사님 [벽/원/포] | K23: 수당률 | L23: 0.5 | M23: =SUM(K25:K32) | N23: =SUM(L25:L32)
B24: NO. | C24: 날짜/예약시간 | E24: 성함 | F24: 연락처 | G24: 주소/주요사항 | H24: 에어컨종류/개수/일반&종합 | I24: 계약금 | J24: 잔금 | K24: 합계 | L24: 수당
B25: 1 | G25: 10시부터 일정 잡아주세요 | K25: =(I25+J25)*10000 | L25: =K25*L23
B26: 2 | K26: =(I26+J26)*10000 | L26: =K26*L23
B27: 3 | K27: =(I27+J27)*10000 | L27: =K27*L23
B28: 4 | K28: =(I28+J28)*10000 | L28: =K28*L23
B29: 5 | K29: =(I29+J29)*10000 | L29: =K29*L23
B30: 6 | K30: =(I30+J30)*10000 | L30: =K30*L23
B31: 7 | K31: =(I31+J31)*10000 | L31: =K31*L23
B32: 8 | K32: =(I32+J32)*10000 | L32: =K32*L23
C33: [김포시] 전상현 기사님 [일정 여유롭게 / 벽/원/스탠드 사무실위주/통] | K33: 수당률 | L33: 0.5 | M33: =SUM(K35:K42) | N33: =SUM(L35:L42)
C34: 날짜/예약시간 | E34: 성함 | F34: 연락처 | G34: 주소/주요사항 | H34: 에어컨종류/개수/일반&종합 | I34: 계약금 | J34: 잔금 | K34: 합계 | L34: 수당 | M34: 포웨이 3시간
K35: =(I35+J35)*10000 | L35: =K35*L33
K36: =(I36+J36)*10000 | L36: =K36*L33
K37: =(I37+J37)*10000 | L37: =K37*L33
K38: =(I38+J38)*10000 | L38: =K38*L33
K39: =(I39+J39)*10000 | L39: =K39*L33
K40: =(I40+J40)*10000 | L40: =K40*L33
K41: =(I41+J41)*10000 | L41: =K41*L33
...

Sheet 22
C1: =DATE(년,월,_xlfn.SHEET()) -> 25569.375 | P1: 금일 매출
C3: 아무것도 잡지마세요 | K3: 수당률 | M3: =SUM(K5:K12) | N3: =SUM(L5:L12)
B4: NO. | C4: 날짜/예약시간 | E4: 성함 | F4: 연락처 | G4: 주소/주요사항 | H4: 에어컨종류/개수/일반&종합 | I4: 계약금 | J4: 잔금 | K4: 합계 | L4: 수당 | P4: 순이익 | Q4: =P10-R10
B5: 1 | K5: =(I5+J5)*10000 | L5: =K5*L3
B6: 2 | K6: =(I6+J6)*10000 | L6: =K6*L3
B7: 3 | K7: =(I7+J7)*10000 | L7: =K7*L3 | P7: 수입 | R7: 지출
B8: 4 | K8: =(I8+J8)*10000 | L8: =K8*L3 | P8: 계약 | Q8: 기타 | R8: 수당비 | S8: 광고비 | T8: 기타
B9: 5 | K9: =(I9+J9)*10000 | L9: =K9*L3 | P9: =SUM(M:M) | R9: =SUM(N:N)
B10: 6 | K10: =(I10+J10)*10000 | L10: =K10*L3 | P10: =SUM(P9:Q9) | R10: =SUM(R9:T9)
B11: 7 | K11: =(I11+J11)*10000 | L11: =K11*L3
B12: 8 | K12: =(I12+J12)*10000 | L12: =K12*L3
C13: [인천시] 김의덕 기사님 [일정 여유롭게 / 벽/원/포/스탠드 사무실위주/고층사다리] | K13: 수당률 | L13: 0.5 | M13: =SUM(K15:K22) | N13: =SUM(L15:L22)
B14: NO. | C14: 날짜/예약시간 | E14: 성함 | F14: 연락처 | G14: 주소/주요사항 | H14: 에어컨종류/개수/일반&종합 | I14: 계약금 | J14: 잔금 | K14: 합계 | L14: 수당 | M14: 고층사다리
B15: 1 | K15: =(I15+J15)*10000 | L15: =K15*L13
B16: 2 | K16: =(I16+J16)*10000 | L16: =K16*L13
B17: 3 | K17: =(I17+J17)*10000 | L17: =K17*L13
B18: 4 | K18: =(I18+J18)*10000 | L18: =K18*L13
B19: 5 | K19: =(I19+J19)*10000 | L19: =K19*L13
B20: 6 | K20: =(I20+J20)*10000 | L20: =K20*L13
B21: 7 | K21: =(I21+J21)*10000 | L21: =K21*L13
B22: 8 | K22: =(I22+J22)*10000 | L22: =K22*L13
C23: [인천 서구/격주토요휴무] 신국관 기사님 [벽/원/포] | K23: 수당률 | L23: 0.5 | M23: =SUM(K25:K32) | N23: =SUM(L25:L32)
B24: NO. | C24: 날짜/예약시간 | E24: 성함 | F24: 연락처 | G24: 주소/주요사항 | H24: 에어컨종류/개수/일반&종합 | I24: 계약금 | J24: 잔금 | K24: 합계 | L24: 수당
B25: 1 | G25: 10시부터 일정 잡아주세요 | K25: =(I25+J25)*10000 | L25: =K25*L23
B26: 2 | K26: =(I26+J26)*10000 | L26: =K26*L23
B27: 3 | K27: =(I27+J27)*10000 | L27: =K27*L23
B28: 4 | K28: =(I28+J28)*10000 | L28: =K28*L23
B29: 5 | K29: =(I29+J29)*10000 | L29: =K29*L23
B30: 6 | K30: =(I30+J30)*10000 | L30: =K30*L23
B31: 7 | K31: =(I31+J31)*10000 | L31: =K31*L23
B32: 8 | K32: =(I32+J32)*10000 | L32: =K32*L23
C33: [김포시] 전상현 기사님 [일정 여유롭게 / 벽/원/스탠드 사무실위주/통] | K33: 수당률 | L33: 0.5 | M33: =SUM(K35:K42) | N33: =SUM(L35:L42)
C34: 날짜/예약시간 | E34: 성함 | F34: 연락처 | G34: 주소/주요사항 | H34: 에어컨종류/개수/일반&종합 | I34: 계약금 | J34: 잔금 | K34: 합계 | L34: 수당 | M34: 포웨이 3시간
K35: =(I35+J35)*10000 | L35: =K35*L33
K36: =(I36+J36)*10000 | L36: =K36*L33
K37: =(I37+J37)*10000 | L37: =K37*L33
K38: =(I38+J38)*10000 | L38: =K38*L33
K39: =(I39+J39)*10000 | L39: =K39*L33
K40: =(I40+J40)*10000 | L40: =K40*L33
K41: =(I41+J41)*10000 | L41: =K41*L33
...

Sheet 23
C1: =DATE(년,월,_xlfn.SHEET()) -> 25569.375 | P1: 금일 매출
C3: 아무것도 잡지마세요 | K3: 수당률 | M3: =SUM(K5:K12) | N3: =SUM(L5:L12)
B4: NO. | C4: 날짜/예약시간 | E4: 성함 | F4: 연락처 | G4: 주소/주요사항 | H4: 에어컨종류/개수/일반&종합 | I4: 계약금 | J4: 잔금 | K4: 합계 | L4: 수당 | P4: 순이익 | Q4: =P10-R10
B5: 1 | K5: =(I5+J5)*10000 | L5: =K5*L3
B6: 2 | K6: =(I6+J6)*10000 | L6: =K6*L3
B7: 3 | K7: =(I7+J7)*10000 | L7: =K7*L3 | P7: 수입 | R7: 지출
B8: 4 | K8: =(I8+J8)*10000 | L8: =K8*L3 | P8: 계약 | Q8: 기타 | R8: 수당비 | S8: 광고비 | T8: 기타
B9: 5 | K9: =(I9+J9)*10000 | L9: =K9*L3 | P9: =SUM(M:M) | R9: =SUM(N:N)
B10: 6 | K10: =(I10+J10)*10000 | L10: =K10*L3 | P10: =SUM(P9:Q9) | R10: =SUM(R9:T9)
B11: 7 | K11: =(I11+J11)*10000 | L11: =K11*L3
B12: 8 | K12: =(I12+J12)*10000 | L12: =K12*L3
C13: [인천시] 김의덕 기사님 [일정 여유롭게 / 벽/원/포/스탠드 사무실위주/고층사다리] | K13: 수당률 | L13: 0.5 | M13: =SUM(K15:K22) | N13: =SUM(L15:L22)
B14: NO. | C14: 날짜/예약시간 | E14: 성함 | F14: 연락처 | G14: 주소/주요사항 | H14: 에어컨종류/개수/일반&종합 | I14: 계약금 | J14: 잔금 | K14: 합계 | L14: 수당 | M14: 고층사다리
B15: 1 | K15: =(I15+J15)*10000 | L15: =K15*L13
B16: 2 | K16: =(I16+J16)*10000 | L16: =K16*L13
B17: 3 | K17: =(I17+J17)*10000 | L17: =K17*L13
B18: 4 | K18: =(I18+J18)*10000 | L18: =K18*L13
B19: 5 | K19: =(I19+J19)*10000 | L19: =K19*L13
B20: 6 | K20: =(I20+J20)*10000 | L20: =K20*L13
B21: 7 | K21: =(I21+J21)*10000 | L21: =K21*L13
B22: 8 | K22: =(I22+J22)*10000 | L22: =K22*L13
C23: [인천 서구/격주토요휴무] 신국관 기사님 [벽/원/포] | K23: 수당률 | L23: 0.5 | M23: =SUM(K25:K32) | N23: =SUM(L25:L32)
B24: NO. | C24: 날짜/예약시간 | E24: 성함 | F24: 연락처 | G24: 주소/주요사항 | H24: 에어컨종류/개수/일반&종합 | I24: 계약금 | J24: 잔금 | K24: 합계 | L24: 수당
B25: 1 | G25: 10시부터 일정 잡아주세요 | K25: =(I25+J25)*10000 | L25: =K25*L23
B26: 2 | K26: =(I26+J26)*10000 | L26: =K26*L23
B27: 3 | K27: =(I27+J27)*10000 | L27: =K27*L23
B28: 4 | K28: =(I28+J28)*10000 | L28: =K28*L23
B29: 5 | K29: =(I29+J29)*10000 | L29: =K29*L23
B30: 6 | K30: =(I30+J30)*10000 | L30: =K30*L23
B31: 7 | K31: =(I31+J31)*10000 | L31: =K31*L23
B32: 8 | K32: =(I32+J32)*10000 | L32: =K32*L23
